Traceback (most recent call last):
  File "/home/kin672/anaconda3/envs/jupytervenv/bin/fast-lineage-caller", line 62, in <module>
    lineage_caller_vcf.assign_lineage_from_vcf_snp_counts(name_file, args.input_file, d[0], d[1], d[2], d[3], print_header, args.out, keep_red, pass_filter)
  File "/home/kin672/anaconda3/envs/jupytervenv/lib/python3.10/site-packages/fast_lineage_caller/lineage_caller_vcf.py", line 65, in assign_lineage_from_vcf_snp_counts
    with open(vcf, "r") as inp:
FileNotFoundError: [Errno 2] No such file or directory: '/n/data1/hms/dbmi/farhat/rollingDB/genomic_data/SAMEA2535310/pilon/SAMEA2535310.vcf'
Traceback (most recent call last):
  File "/home/kin672/anaconda3/envs/jupytervenv/bin/fast-lineage-caller", line 62, in <module>
    lineage_caller_vcf.assign_lineage_from_vcf_snp_counts(name_file, args.input_file, d[0], d[1], d[2], d[3], print_header, args.out, keep_red, pass_filter)
  File "/home/kin672/anaconda3/envs/jupytervenv/lib/python3.10/site-packages/fast_lineage_caller/lineage_caller_vcf.py", line 65, in assign_lineage_from_vcf_snp_counts
    with open(vcf, "r") as inp:
FileNotFoundError: [Errno 2] No such file or directory: '/n/data1/hms/dbmi/farhat/rollingDB/genomic_data/SAMEA2535274/pilon/SAMEA2535274.vcf'
Traceback (most recent call last):
  File "/home/kin672/anaconda3/envs/jupytervenv/bin/fast-lineage-caller", line 62, in <module>
    lineage_caller_vcf.assign_lineage_from_vcf_snp_counts(name_file, args.input_file, d[0], d[1], d[2], d[3], print_header, args.out, keep_red, pass_filter)
  File "/home/kin672/anaconda3/envs/jupytervenv/lib/python3.10/site-packages/fast_lineage_caller/lineage_caller_vcf.py", line 65, in assign_lineage_from_vcf_snp_counts
    with open(vcf, "r") as inp:
FileNotFoundError: [Errno 2] No such file or directory: '/n/data1/hms/dbmi/farhat/rollingDB/genomic_data/SAMEA2535241/pilon/SAMEA2535241.vcf'
Traceback (most recent call last):
  File "/home/kin672/anaconda3/envs/jupytervenv/bin/fast-lineage-caller", line 62, in <module>
    lineage_caller_vcf.assign_lineage_from_vcf_snp_counts(name_file, args.input_file, d[0], d[1], d[2], d[3], print_header, args.out, keep_red, pass_filter)
  File "/home/kin672/anaconda3/envs/jupytervenv/lib/python3.10/site-packages/fast_lineage_caller/lineage_caller_vcf.py", line 65, in assign_lineage_from_vcf_snp_counts
    with open(vcf, "r") as inp:
FileNotFoundError: [Errno 2] No such file or directory: '/n/data1/hms/dbmi/farhat/rollingDB/genomic_data/SAMEA2535221/pilon/SAMEA2535221.vcf'
Traceback (most recent call last):
  File "/home/kin672/anaconda3/envs/jupytervenv/bin/fast-lineage-caller", line 62, in <module>
    lineage_caller_vcf.assign_lineage_from_vcf_snp_counts(name_file, args.input_file, d[0], d[1], d[2], d[3], print_header, args.out, keep_red, pass_filter)
  File "/home/kin672/anaconda3/envs/jupytervenv/lib/python3.10/site-packages/fast_lineage_caller/lineage_caller_vcf.py", line 65, in assign_lineage_from_vcf_snp_counts
    with open(vcf, "r") as inp:
FileNotFoundError: [Errno 2] No such file or directory: '/n/data1/hms/dbmi/farhat/rollingDB/genomic_data/SAMEA2535217/pilon/SAMEA2535217.vcf'
Traceback (most recent call last):
  File "/home/kin672/anaconda3/envs/jupytervenv/bin/fast-lineage-caller", line 62, in <module>
    lineage_caller_vcf.assign_lineage_from_vcf_snp_counts(name_file, args.input_file, d[0], d[1], d[2], d[3], print_header, args.out, keep_red, pass_filter)
  File "/home/kin672/anaconda3/envs/jupytervenv/lib/python3.10/site-packages/fast_lineage_caller/lineage_caller_vcf.py", line 65, in assign_lineage_from_vcf_snp_counts
    with open(vcf, "r") as inp:
FileNotFoundError: [Errno 2] No such file or directory: '/n/data1/hms/dbmi/farhat/rollingDB/genomic_data/SAMEA2535076/pilon/SAMEA2535076.vcf'
Traceback (most recent call last):
  File "/home/kin672/anaconda3/envs/jupytervenv/bin/fast-lineage-caller", line 62, in <module>
    lineage_caller_vcf.assign_lineage_from_vcf_snp_counts(name_file, args.input_file, d[0], d[1], d[2], d[3], print_header, args.out, keep_red, pass_filter)
  File "/home/kin672/anaconda3/envs/jupytervenv/lib/python3.10/site-packages/fast_lineage_caller/lineage_caller_vcf.py", line 65, in assign_lineage_from_vcf_snp_counts
    with open(vcf, "r") as inp:
FileNotFoundError: [Errno 2] No such file or directory: '/n/data1/hms/dbmi/farhat/rollingDB/genomic_data/SAMEA2535060/pilon/SAMEA2535060.vcf'
Traceback (most recent call last):
  File "/home/kin672/anaconda3/envs/jupytervenv/bin/fast-lineage-caller", line 62, in <module>
    lineage_caller_vcf.assign_lineage_from_vcf_snp_counts(name_file, args.input_file, d[0], d[1], d[2], d[3], print_header, args.out, keep_red, pass_filter)
  File "/home/kin672/anaconda3/envs/jupytervenv/lib/python3.10/site-packages/fast_lineage_caller/lineage_caller_vcf.py", line 65, in assign_lineage_from_vcf_snp_counts
    with open(vcf, "r") as inp:
FileNotFoundError: [Errno 2] No such file or directory: '/n/data1/hms/dbmi/farhat/rollingDB/genomic_data/SAMEA2535055/pilon/SAMEA2535055.vcf'
Traceback (most recent call last):
  File "/home/kin672/anaconda3/envs/jupytervenv/bin/fast-lineage-caller", line 62, in <module>
    lineage_caller_vcf.assign_lineage_from_vcf_snp_counts(name_file, args.input_file, d[0], d[1], d[2], d[3], print_header, args.out, keep_red, pass_filter)
  File "/home/kin672/anaconda3/envs/jupytervenv/lib/python3.10/site-packages/fast_lineage_caller/lineage_caller_vcf.py", line 65, in assign_lineage_from_vcf_snp_counts
    with open(vcf, "r") as inp:
FileNotFoundError: [Errno 2] No such file or directory: '/n/data1/hms/dbmi/farhat/rollingDB/genomic_data/SAMEA2534996/pilon/SAMEA2534996.vcf'
Traceback (most recent call last):
  File "/home/kin672/anaconda3/envs/jupytervenv/bin/fast-lineage-caller", line 62, in <module>
    lineage_caller_vcf.assign_lineage_from_vcf_snp_counts(name_file, args.input_file, d[0], d[1], d[2], d[3], print_header, args.out, keep_red, pass_filter)
  File "/home/kin672/anaconda3/envs/jupytervenv/lib/python3.10/site-packages/fast_lineage_caller/lineage_caller_vcf.py", line 65, in assign_lineage_from_vcf_snp_counts
    with open(vcf, "r") as inp:
FileNotFoundError: [Errno 2] No such file or directory: '/n/data1/hms/dbmi/farhat/rollingDB/genomic_data/SAMEA2534571/pilon/SAMEA2534571.vcf'
Traceback (most recent call last):
  File "/home/kin672/anaconda3/envs/jupytervenv/bin/fast-lineage-caller", line 62, in <module>
    lineage_caller_vcf.assign_lineage_from_vcf_snp_counts(name_file, args.input_file, d[0], d[1], d[2], d[3], print_header, args.out, keep_red, pass_filter)
  File "/home/kin672/anaconda3/envs/jupytervenv/lib/python3.10/site-packages/fast_lineage_caller/lineage_caller_vcf.py", line 65, in assign_lineage_from_vcf_snp_counts
    with open(vcf, "r") as inp:
FileNotFoundError: [Errno 2] No such file or directory: '/n/data1/hms/dbmi/farhat/rollingDB/genomic_data/SAMEA2534558/pilon/SAMEA2534558.vcf'
Traceback (most recent call last):
  File "/home/kin672/anaconda3/envs/jupytervenv/bin/fast-lineage-caller", line 62, in <module>
    lineage_caller_vcf.assign_lineage_from_vcf_snp_counts(name_file, args.input_file, d[0], d[1], d[2], d[3], print_header, args.out, keep_red, pass_filter)
  File "/home/kin672/anaconda3/envs/jupytervenv/lib/python3.10/site-packages/fast_lineage_caller/lineage_caller_vcf.py", line 65, in assign_lineage_from_vcf_snp_counts
    with open(vcf, "r") as inp:
FileNotFoundError: [Errno 2] No such file or directory: '/n/data1/hms/dbmi/farhat/rollingDB/genomic_data/SAMEA2534544/pilon/SAMEA2534544.vcf'
Traceback (most recent call last):
  File "/home/kin672/anaconda3/envs/jupytervenv/bin/fast-lineage-caller", line 62, in <module>
    lineage_caller_vcf.assign_lineage_from_vcf_snp_counts(name_file, args.input_file, d[0], d[1], d[2], d[3], print_header, args.out, keep_red, pass_filter)
  File "/home/kin672/anaconda3/envs/jupytervenv/lib/python3.10/site-packages/fast_lineage_caller/lineage_caller_vcf.py", line 65, in assign_lineage_from_vcf_snp_counts
    with open(vcf, "r") as inp:
FileNotFoundError: [Errno 2] No such file or directory: '/n/data1/hms/dbmi/farhat/rollingDB/genomic_data/SAMEA2534541/pilon/SAMEA2534541.vcf'
Traceback (most recent call last):
  File "/home/kin672/anaconda3/envs/jupytervenv/bin/fast-lineage-caller", line 62, in <module>
    lineage_caller_vcf.assign_lineage_from_vcf_snp_counts(name_file, args.input_file, d[0], d[1], d[2], d[3], print_header, args.out, keep_red, pass_filter)
  File "/home/kin672/anaconda3/envs/jupytervenv/lib/python3.10/site-packages/fast_lineage_caller/lineage_caller_vcf.py", line 65, in assign_lineage_from_vcf_snp_counts
    with open(vcf, "r") as inp:
FileNotFoundError: [Errno 2] No such file or directory: '/n/data1/hms/dbmi/farhat/rollingDB/genomic_data/SAMEA2534468/pilon/SAMEA2534468.vcf'
Traceback (most recent call last):
  File "/home/kin672/anaconda3/envs/jupytervenv/bin/fast-lineage-caller", line 62, in <module>
    lineage_caller_vcf.assign_lineage_from_vcf_snp_counts(name_file, args.input_file, d[0], d[1], d[2], d[3], print_header, args.out, keep_red, pass_filter)
  File "/home/kin672/anaconda3/envs/jupytervenv/lib/python3.10/site-packages/fast_lineage_caller/lineage_caller_vcf.py", line 65, in assign_lineage_from_vcf_snp_counts
    with open(vcf, "r") as inp:
FileNotFoundError: [Errno 2] No such file or directory: '/n/data1/hms/dbmi/farhat/rollingDB/genomic_data/SAMEA2534447/pilon/SAMEA2534447.vcf'
Traceback (most recent call last):
  File "/home/kin672/anaconda3/envs/jupytervenv/bin/fast-lineage-caller", line 62, in <module>
    lineage_caller_vcf.assign_lineage_from_vcf_snp_counts(name_file, args.input_file, d[0], d[1], d[2], d[3], print_header, args.out, keep_red, pass_filter)
  File "/home/kin672/anaconda3/envs/jupytervenv/lib/python3.10/site-packages/fast_lineage_caller/lineage_caller_vcf.py", line 65, in assign_lineage_from_vcf_snp_counts
    with open(vcf, "r") as inp:
FileNotFoundError: [Errno 2] No such file or directory: '/n/data1/hms/dbmi/farhat/rollingDB/genomic_data/SAMEA2534323/pilon/SAMEA2534323.vcf'
Traceback (most recent call last):
  File "/home/kin672/anaconda3/envs/jupytervenv/bin/fast-lineage-caller", line 62, in <module>
    lineage_caller_vcf.assign_lineage_from_vcf_snp_counts(name_file, args.input_file, d[0], d[1], d[2], d[3], print_header, args.out, keep_red, pass_filter)
  File "/home/kin672/anaconda3/envs/jupytervenv/lib/python3.10/site-packages/fast_lineage_caller/lineage_caller_vcf.py", line 65, in assign_lineage_from_vcf_snp_counts
    with open(vcf, "r") as inp:
FileNotFoundError: [Errno 2] No such file or directory: '/n/data1/hms/dbmi/farhat/rollingDB/genomic_data/SAMEA2534291/pilon/SAMEA2534291.vcf'
Traceback (most recent call last):
  File "/home/kin672/anaconda3/envs/jupytervenv/bin/fast-lineage-caller", line 62, in <module>
    lineage_caller_vcf.assign_lineage_from_vcf_snp_counts(name_file, args.input_file, d[0], d[1], d[2], d[3], print_header, args.out, keep_red, pass_filter)
  File "/home/kin672/anaconda3/envs/jupytervenv/lib/python3.10/site-packages/fast_lineage_caller/lineage_caller_vcf.py", line 65, in assign_lineage_from_vcf_snp_counts
    with open(vcf, "r") as inp:
FileNotFoundError: [Errno 2] No such file or directory: '/n/data1/hms/dbmi/farhat/rollingDB/genomic_data/SAMEA2534272/pilon/SAMEA2534272.vcf'
Traceback (most recent call last):
  File "/home/kin672/anaconda3/envs/jupytervenv/bin/fast-lineage-caller", line 62, in <module>
    lineage_caller_vcf.assign_lineage_from_vcf_snp_counts(name_file, args.input_file, d[0], d[1], d[2], d[3], print_header, args.out, keep_red, pass_filter)
  File "/home/kin672/anaconda3/envs/jupytervenv/lib/python3.10/site-packages/fast_lineage_caller/lineage_caller_vcf.py", line 65, in assign_lineage_from_vcf_snp_counts
    with open(vcf, "r") as inp:
FileNotFoundError: [Errno 2] No such file or directory: '/n/data1/hms/dbmi/farhat/rollingDB/genomic_data/SAMEA2534240/pilon/SAMEA2534240.vcf'
Traceback (most recent call last):
  File "/home/kin672/anaconda3/envs/jupytervenv/bin/fast-lineage-caller", line 62, in <module>
    lineage_caller_vcf.assign_lineage_from_vcf_snp_counts(name_file, args.input_file, d[0], d[1], d[2], d[3], print_header, args.out, keep_red, pass_filter)
  File "/home/kin672/anaconda3/envs/jupytervenv/lib/python3.10/site-packages/fast_lineage_caller/lineage_caller_vcf.py", line 65, in assign_lineage_from_vcf_snp_counts
    with open(vcf, "r") as inp:
FileNotFoundError: [Errno 2] No such file or directory: '/n/data1/hms/dbmi/farhat/rollingDB/genomic_data/SAMEA2534172/pilon/SAMEA2534172.vcf'
Traceback (most recent call last):
  File "/home/kin672/anaconda3/envs/jupytervenv/bin/fast-lineage-caller", line 62, in <module>
    lineage_caller_vcf.assign_lineage_from_vcf_snp_counts(name_file, args.input_file, d[0], d[1], d[2], d[3], print_header, args.out, keep_red, pass_filter)
  File "/home/kin672/anaconda3/envs/jupytervenv/lib/python3.10/site-packages/fast_lineage_caller/lineage_caller_vcf.py", line 65, in assign_lineage_from_vcf_snp_counts
    with open(vcf, "r") as inp:
FileNotFoundError: [Errno 2] No such file or directory: '/n/data1/hms/dbmi/farhat/rollingDB/genomic_data/SAMEA2534108/pilon/SAMEA2534108.vcf'
Traceback (most recent call last):
  File "/home/kin672/anaconda3/envs/jupytervenv/bin/fast-lineage-caller", line 62, in <module>
    lineage_caller_vcf.assign_lineage_from_vcf_snp_counts(name_file, args.input_file, d[0], d[1], d[2], d[3], print_header, args.out, keep_red, pass_filter)
  File "/home/kin672/anaconda3/envs/jupytervenv/lib/python3.10/site-packages/fast_lineage_caller/lineage_caller_vcf.py", line 65, in assign_lineage_from_vcf_snp_counts
    with open(vcf, "r") as inp:
FileNotFoundError: [Errno 2] No such file or directory: '/n/data1/hms/dbmi/farhat/rollingDB/genomic_data/SAMEA2534048/pilon/SAMEA2534048.vcf'
Traceback (most recent call last):
  File "/home/kin672/anaconda3/envs/jupytervenv/bin/fast-lineage-caller", line 62, in <module>
    lineage_caller_vcf.assign_lineage_from_vcf_snp_counts(name_file, args.input_file, d[0], d[1], d[2], d[3], print_header, args.out, keep_red, pass_filter)
  File "/home/kin672/anaconda3/envs/jupytervenv/lib/python3.10/site-packages/fast_lineage_caller/lineage_caller_vcf.py", line 65, in assign_lineage_from_vcf_snp_counts
    with open(vcf, "r") as inp:
FileNotFoundError: [Errno 2] No such file or directory: '/n/data1/hms/dbmi/farhat/rollingDB/genomic_data/SAMEA2533965/pilon/SAMEA2533965.vcf'
Traceback (most recent call last):
  File "/home/kin672/anaconda3/envs/jupytervenv/bin/fast-lineage-caller", line 62, in <module>
    lineage_caller_vcf.assign_lineage_from_vcf_snp_counts(name_file, args.input_file, d[0], d[1], d[2], d[3], print_header, args.out, keep_red, pass_filter)
  File "/home/kin672/anaconda3/envs/jupytervenv/lib/python3.10/site-packages/fast_lineage_caller/lineage_caller_vcf.py", line 65, in assign_lineage_from_vcf_snp_counts
    with open(vcf, "r") as inp:
FileNotFoundError: [Errno 2] No such file or directory: '/n/data1/hms/dbmi/farhat/rollingDB/genomic_data/SAMEA2533861/pilon/SAMEA2533861.vcf'
Traceback (most recent call last):
  File "/home/kin672/anaconda3/envs/jupytervenv/bin/fast-lineage-caller", line 62, in <module>
    lineage_caller_vcf.assign_lineage_from_vcf_snp_counts(name_file, args.input_file, d[0], d[1], d[2], d[3], print_header, args.out, keep_red, pass_filter)
  File "/home/kin672/anaconda3/envs/jupytervenv/lib/python3.10/site-packages/fast_lineage_caller/lineage_caller_vcf.py", line 65, in assign_lineage_from_vcf_snp_counts
    with open(vcf, "r") as inp:
FileNotFoundError: [Errno 2] No such file or directory: '/n/data1/hms/dbmi/farhat/rollingDB/genomic_data/SAMEA2533854/pilon/SAMEA2533854.vcf'
Traceback (most recent call last):
  File "/home/kin672/anaconda3/envs/jupytervenv/bin/fast-lineage-caller", line 62, in <module>
    lineage_caller_vcf.assign_lineage_from_vcf_snp_counts(name_file, args.input_file, d[0], d[1], d[2], d[3], print_header, args.out, keep_red, pass_filter)
  File "/home/kin672/anaconda3/envs/jupytervenv/lib/python3.10/site-packages/fast_lineage_caller/lineage_caller_vcf.py", line 65, in assign_lineage_from_vcf_snp_counts
    with open(vcf, "r") as inp:
FileNotFoundError: [Errno 2] No such file or directory: '/n/data1/hms/dbmi/farhat/rollingDB/genomic_data/SAMEA2533774/pilon/SAMEA2533774.vcf'
Traceback (most recent call last):
  File "/home/kin672/anaconda3/envs/jupytervenv/bin/fast-lineage-caller", line 62, in <module>
    lineage_caller_vcf.assign_lineage_from_vcf_snp_counts(name_file, args.input_file, d[0], d[1], d[2], d[3], print_header, args.out, keep_red, pass_filter)
  File "/home/kin672/anaconda3/envs/jupytervenv/lib/python3.10/site-packages/fast_lineage_caller/lineage_caller_vcf.py", line 65, in assign_lineage_from_vcf_snp_counts
    with open(vcf, "r") as inp:
FileNotFoundError: [Errno 2] No such file or directory: '/n/data1/hms/dbmi/farhat/rollingDB/genomic_data/SAMEA2533766/pilon/SAMEA2533766.vcf'
Traceback (most recent call last):
  File "/home/kin672/anaconda3/envs/jupytervenv/bin/fast-lineage-caller", line 62, in <module>
    lineage_caller_vcf.assign_lineage_from_vcf_snp_counts(name_file, args.input_file, d[0], d[1], d[2], d[3], print_header, args.out, keep_red, pass_filter)
  File "/home/kin672/anaconda3/envs/jupytervenv/lib/python3.10/site-packages/fast_lineage_caller/lineage_caller_vcf.py", line 65, in assign_lineage_from_vcf_snp_counts
    with open(vcf, "r") as inp:
FileNotFoundError: [Errno 2] No such file or directory: '/n/data1/hms/dbmi/farhat/rollingDB/genomic_data/SAMEA2533717/pilon/SAMEA2533717.vcf'
Traceback (most recent call last):
  File "/home/kin672/anaconda3/envs/jupytervenv/bin/fast-lineage-caller", line 62, in <module>
    lineage_caller_vcf.assign_lineage_from_vcf_snp_counts(name_file, args.input_file, d[0], d[1], d[2], d[3], print_header, args.out, keep_red, pass_filter)
  File "/home/kin672/anaconda3/envs/jupytervenv/lib/python3.10/site-packages/fast_lineage_caller/lineage_caller_vcf.py", line 65, in assign_lineage_from_vcf_snp_counts
    with open(vcf, "r") as inp:
FileNotFoundError: [Errno 2] No such file or directory: '/n/data1/hms/dbmi/farhat/rollingDB/genomic_data/SAMEA2533549/pilon/SAMEA2533549.vcf'
Traceback (most recent call last):
  File "/home/kin672/anaconda3/envs/jupytervenv/bin/fast-lineage-caller", line 62, in <module>
    lineage_caller_vcf.assign_lineage_from_vcf_snp_counts(name_file, args.input_file, d[0], d[1], d[2], d[3], print_header, args.out, keep_red, pass_filter)
  File "/home/kin672/anaconda3/envs/jupytervenv/lib/python3.10/site-packages/fast_lineage_caller/lineage_caller_vcf.py", line 65, in assign_lineage_from_vcf_snp_counts
    with open(vcf, "r") as inp:
FileNotFoundError: [Errno 2] No such file or directory: '/n/data1/hms/dbmi/farhat/rollingDB/genomic_data/SAMEA2533528/pilon/SAMEA2533528.vcf'
Traceback (most recent call last):
  File "/home/kin672/anaconda3/envs/jupytervenv/bin/fast-lineage-caller", line 62, in <module>
    lineage_caller_vcf.assign_lineage_from_vcf_snp_counts(name_file, args.input_file, d[0], d[1], d[2], d[3], print_header, args.out, keep_red, pass_filter)
  File "/home/kin672/anaconda3/envs/jupytervenv/lib/python3.10/site-packages/fast_lineage_caller/lineage_caller_vcf.py", line 65, in assign_lineage_from_vcf_snp_counts
    with open(vcf, "r") as inp:
FileNotFoundError: [Errno 2] No such file or directory: '/n/data1/hms/dbmi/farhat/rollingDB/genomic_data/SAMEA2533419/pilon/SAMEA2533419.vcf'
Traceback (most recent call last):
  File "/home/kin672/anaconda3/envs/jupytervenv/bin/fast-lineage-caller", line 62, in <module>
    lineage_caller_vcf.assign_lineage_from_vcf_snp_counts(name_file, args.input_file, d[0], d[1], d[2], d[3], print_header, args.out, keep_red, pass_filter)
  File "/home/kin672/anaconda3/envs/jupytervenv/lib/python3.10/site-packages/fast_lineage_caller/lineage_caller_vcf.py", line 65, in assign_lineage_from_vcf_snp_counts
    with open(vcf, "r") as inp:
FileNotFoundError: [Errno 2] No such file or directory: '/n/data1/hms/dbmi/farhat/rollingDB/genomic_data/SAMEA2533360/pilon/SAMEA2533360.vcf'
Traceback (most recent call last):
  File "/home/kin672/anaconda3/envs/jupytervenv/bin/fast-lineage-caller", line 62, in <module>
    lineage_caller_vcf.assign_lineage_from_vcf_snp_counts(name_file, args.input_file, d[0], d[1], d[2], d[3], print_header, args.out, keep_red, pass_filter)
  File "/home/kin672/anaconda3/envs/jupytervenv/lib/python3.10/site-packages/fast_lineage_caller/lineage_caller_vcf.py", line 65, in assign_lineage_from_vcf_snp_counts
    with open(vcf, "r") as inp:
FileNotFoundError: [Errno 2] No such file or directory: '/n/data1/hms/dbmi/farhat/rollingDB/genomic_data/SAMEA2533346/pilon/SAMEA2533346.vcf'
Traceback (most recent call last):
  File "/home/kin672/anaconda3/envs/jupytervenv/bin/fast-lineage-caller", line 62, in <module>
    lineage_caller_vcf.assign_lineage_from_vcf_snp_counts(name_file, args.input_file, d[0], d[1], d[2], d[3], print_header, args.out, keep_red, pass_filter)
  File "/home/kin672/anaconda3/envs/jupytervenv/lib/python3.10/site-packages/fast_lineage_caller/lineage_caller_vcf.py", line 65, in assign_lineage_from_vcf_snp_counts
    with open(vcf, "r") as inp:
FileNotFoundError: [Errno 2] No such file or directory: '/n/data1/hms/dbmi/farhat/rollingDB/genomic_data/SAMEA2517417/pilon/SAMEA2517417.vcf'
Traceback (most recent call last):
  File "/home/kin672/anaconda3/envs/jupytervenv/bin/fast-lineage-caller", line 62, in <module>
    lineage_caller_vcf.assign_lineage_from_vcf_snp_counts(name_file, args.input_file, d[0], d[1], d[2], d[3], print_header, args.out, keep_red, pass_filter)
  File "/home/kin672/anaconda3/envs/jupytervenv/lib/python3.10/site-packages/fast_lineage_caller/lineage_caller_vcf.py", line 65, in assign_lineage_from_vcf_snp_counts
    with open(vcf, "r") as inp:
FileNotFoundError: [Errno 2] No such file or directory: '/n/data1/hms/dbmi/farhat/rollingDB/genomic_data/SAMEA2517416/pilon/SAMEA2517416.vcf'
Traceback (most recent call last):
  File "/home/kin672/anaconda3/envs/jupytervenv/bin/fast-lineage-caller", line 62, in <module>
    lineage_caller_vcf.assign_lineage_from_vcf_snp_counts(name_file, args.input_file, d[0], d[1], d[2], d[3], print_header, args.out, keep_red, pass_filter)
  File "/home/kin672/anaconda3/envs/jupytervenv/lib/python3.10/site-packages/fast_lineage_caller/lineage_caller_vcf.py", line 65, in assign_lineage_from_vcf_snp_counts
    with open(vcf, "r") as inp:
FileNotFoundError: [Errno 2] No such file or directory: '/n/data1/hms/dbmi/farhat/rollingDB/genomic_data/SAMEA2517357/pilon/SAMEA2517357.vcf'
Traceback (most recent call last):
  File "/home/kin672/anaconda3/envs/jupytervenv/bin/fast-lineage-caller", line 62, in <module>
    lineage_caller_vcf.assign_lineage_from_vcf_snp_counts(name_file, args.input_file, d[0], d[1], d[2], d[3], print_header, args.out, keep_red, pass_filter)
  File "/home/kin672/anaconda3/envs/jupytervenv/lib/python3.10/site-packages/fast_lineage_caller/lineage_caller_vcf.py", line 65, in assign_lineage_from_vcf_snp_counts
    with open(vcf, "r") as inp:
FileNotFoundError: [Errno 2] No such file or directory: '/n/data1/hms/dbmi/farhat/rollingDB/cryptic_output/ERR2510833/pilon/ERR2510833.vcf'
Traceback (most recent call last):
  File "/home/kin672/anaconda3/envs/jupytervenv/bin/fast-lineage-caller", line 62, in <module>
    lineage_caller_vcf.assign_lineage_from_vcf_snp_counts(name_file, args.input_file, d[0], d[1], d[2], d[3], print_header, args.out, keep_red, pass_filter)
  File "/home/kin672/anaconda3/envs/jupytervenv/lib/python3.10/site-packages/fast_lineage_caller/lineage_caller_vcf.py", line 65, in assign_lineage_from_vcf_snp_counts
    with open(vcf, "r") as inp:
FileNotFoundError: [Errno 2] No such file or directory: '/n/data1/hms/dbmi/farhat/rollingDB/cryptic_output/ERR2510682/pilon/ERR2510682.vcf'
Traceback (most recent call last):
  File "/home/kin672/anaconda3/envs/jupytervenv/bin/fast-lineage-caller", line 62, in <module>
    lineage_caller_vcf.assign_lineage_from_vcf_snp_counts(name_file, args.input_file, d[0], d[1], d[2], d[3], print_header, args.out, keep_red, pass_filter)
  File "/home/kin672/anaconda3/envs/jupytervenv/lib/python3.10/site-packages/fast_lineage_caller/lineage_caller_vcf.py", line 65, in assign_lineage_from_vcf_snp_counts
    with open(vcf, "r") as inp:
FileNotFoundError: [Errno 2] No such file or directory: '/n/data1/hms/dbmi/farhat/rollingDB/cryptic_output/ERR2510633/pilon/ERR2510633.vcf'
Traceback (most recent call last):
  File "/home/kin672/anaconda3/envs/jupytervenv/bin/fast-lineage-caller", line 62, in <module>
    lineage_caller_vcf.assign_lineage_from_vcf_snp_counts(name_file, args.input_file, d[0], d[1], d[2], d[3], print_header, args.out, keep_red, pass_filter)
  File "/home/kin672/anaconda3/envs/jupytervenv/lib/python3.10/site-packages/fast_lineage_caller/lineage_caller_vcf.py", line 65, in assign_lineage_from_vcf_snp_counts
    with open(vcf, "r") as inp:
FileNotFoundError: [Errno 2] No such file or directory: '/n/data1/hms/dbmi/farhat/rollingDB/cryptic_output/ERR2510628/pilon/ERR2510628.vcf'
Traceback (most recent call last):
  File "/home/kin672/anaconda3/envs/jupytervenv/bin/fast-lineage-caller", line 62, in <module>
    lineage_caller_vcf.assign_lineage_from_vcf_snp_counts(name_file, args.input_file, d[0], d[1], d[2], d[3], print_header, args.out, keep_red, pass_filter)
  File "/home/kin672/anaconda3/envs/jupytervenv/lib/python3.10/site-packages/fast_lineage_caller/lineage_caller_vcf.py", line 65, in assign_lineage_from_vcf_snp_counts
    with open(vcf, "r") as inp:
FileNotFoundError: [Errno 2] No such file or directory: '/n/data1/hms/dbmi/farhat/rollingDB/cryptic_output/ERR2510607/pilon/ERR2510607.vcf'
Traceback (most recent call last):
  File "/home/kin672/anaconda3/envs/jupytervenv/bin/fast-lineage-caller", line 62, in <module>
    lineage_caller_vcf.assign_lineage_from_vcf_snp_counts(name_file, args.input_file, d[0], d[1], d[2], d[3], print_header, args.out, keep_red, pass_filter)
  File "/home/kin672/anaconda3/envs/jupytervenv/lib/python3.10/site-packages/fast_lineage_caller/lineage_caller_vcf.py", line 65, in assign_lineage_from_vcf_snp_counts
    with open(vcf, "r") as inp:
FileNotFoundError: [Errno 2] No such file or directory: '/n/data1/hms/dbmi/farhat/rollingDB/cryptic_output/ERR2510593/pilon/ERR2510593.vcf'
Traceback (most recent call last):
  File "/home/kin672/anaconda3/envs/jupytervenv/bin/fast-lineage-caller", line 62, in <module>
    lineage_caller_vcf.assign_lineage_from_vcf_snp_counts(name_file, args.input_file, d[0], d[1], d[2], d[3], print_header, args.out, keep_red, pass_filter)
  File "/home/kin672/anaconda3/envs/jupytervenv/lib/python3.10/site-packages/fast_lineage_caller/lineage_caller_vcf.py", line 65, in assign_lineage_from_vcf_snp_counts
    with open(vcf, "r") as inp:
FileNotFoundError: [Errno 2] No such file or directory: '/n/data1/hms/dbmi/farhat/rollingDB/cryptic_output/ERR2510541/pilon/ERR2510541.vcf'
Traceback (most recent call last):
  File "/home/kin672/anaconda3/envs/jupytervenv/bin/fast-lineage-caller", line 62, in <module>
    lineage_caller_vcf.assign_lineage_from_vcf_snp_counts(name_file, args.input_file, d[0], d[1], d[2], d[3], print_header, args.out, keep_red, pass_filter)
  File "/home/kin672/anaconda3/envs/jupytervenv/lib/python3.10/site-packages/fast_lineage_caller/lineage_caller_vcf.py", line 65, in assign_lineage_from_vcf_snp_counts
    with open(vcf, "r") as inp:
FileNotFoundError: [Errno 2] No such file or directory: '/n/data1/hms/dbmi/farhat/rollingDB/cryptic_output/ERR2510531/pilon/ERR2510531.vcf'
Traceback (most recent call last):
  File "/home/kin672/anaconda3/envs/jupytervenv/bin/fast-lineage-caller", line 62, in <module>
    lineage_caller_vcf.assign_lineage_from_vcf_snp_counts(name_file, args.input_file, d[0], d[1], d[2], d[3], print_header, args.out, keep_red, pass_filter)
  File "/home/kin672/anaconda3/envs/jupytervenv/lib/python3.10/site-packages/fast_lineage_caller/lineage_caller_vcf.py", line 65, in assign_lineage_from_vcf_snp_counts
    with open(vcf, "r") as inp:
FileNotFoundError: [Errno 2] No such file or directory: '/n/data1/hms/dbmi/farhat/rollingDB/cryptic_output/ERR2510509/pilon/ERR2510509.vcf'
Traceback (most recent call last):
  File "/home/kin672/anaconda3/envs/jupytervenv/bin/fast-lineage-caller", line 62, in <module>
    lineage_caller_vcf.assign_lineage_from_vcf_snp_counts(name_file, args.input_file, d[0], d[1], d[2], d[3], print_header, args.out, keep_red, pass_filter)
  File "/home/kin672/anaconda3/envs/jupytervenv/lib/python3.10/site-packages/fast_lineage_caller/lineage_caller_vcf.py", line 65, in assign_lineage_from_vcf_snp_counts
    with open(vcf, "r") as inp:
FileNotFoundError: [Errno 2] No such file or directory: '/n/data1/hms/dbmi/farhat/rollingDB/cryptic_output/ERR2510482/pilon/ERR2510482.vcf'
Traceback (most recent call last):
  File "/home/kin672/anaconda3/envs/jupytervenv/bin/fast-lineage-caller", line 62, in <module>
    lineage_caller_vcf.assign_lineage_from_vcf_snp_counts(name_file, args.input_file, d[0], d[1], d[2], d[3], print_header, args.out, keep_red, pass_filter)
  File "/home/kin672/anaconda3/envs/jupytervenv/lib/python3.10/site-packages/fast_lineage_caller/lineage_caller_vcf.py", line 65, in assign_lineage_from_vcf_snp_counts
    with open(vcf, "r") as inp:
FileNotFoundError: [Errno 2] No such file or directory: '/n/data1/hms/dbmi/farhat/rollingDB/cryptic_output/ERR2510420/pilon/ERR2510420.vcf'
Traceback (most recent call last):
  File "/home/kin672/anaconda3/envs/jupytervenv/bin/fast-lineage-caller", line 62, in <module>
    lineage_caller_vcf.assign_lineage_from_vcf_snp_counts(name_file, args.input_file, d[0], d[1], d[2], d[3], print_header, args.out, keep_red, pass_filter)
  File "/home/kin672/anaconda3/envs/jupytervenv/lib/python3.10/site-packages/fast_lineage_caller/lineage_caller_vcf.py", line 65, in assign_lineage_from_vcf_snp_counts
    with open(vcf, "r") as inp:
FileNotFoundError: [Errno 2] No such file or directory: '/n/data1/hms/dbmi/farhat/rollingDB/cryptic_output/ERR2510407/pilon/ERR2510407.vcf'
Traceback (most recent call last):
  File "/home/kin672/anaconda3/envs/jupytervenv/bin/fast-lineage-caller", line 62, in <module>
    lineage_caller_vcf.assign_lineage_from_vcf_snp_counts(name_file, args.input_file, d[0], d[1], d[2], d[3], print_header, args.out, keep_red, pass_filter)
  File "/home/kin672/anaconda3/envs/jupytervenv/lib/python3.10/site-packages/fast_lineage_caller/lineage_caller_vcf.py", line 65, in assign_lineage_from_vcf_snp_counts
    with open(vcf, "r") as inp:
FileNotFoundError: [Errno 2] No such file or directory: '/n/data1/hms/dbmi/farhat/rollingDB/cryptic_output/ERR2510395/pilon/ERR2510395.vcf'
Traceback (most recent call last):
  File "/home/kin672/anaconda3/envs/jupytervenv/bin/fast-lineage-caller", line 62, in <module>
    lineage_caller_vcf.assign_lineage_from_vcf_snp_counts(name_file, args.input_file, d[0], d[1], d[2], d[3], print_header, args.out, keep_red, pass_filter)
  File "/home/kin672/anaconda3/envs/jupytervenv/lib/python3.10/site-packages/fast_lineage_caller/lineage_caller_vcf.py", line 65, in assign_lineage_from_vcf_snp_counts
    with open(vcf, "r") as inp:
FileNotFoundError: [Errno 2] No such file or directory: '/n/data1/hms/dbmi/farhat/rollingDB/cryptic_output/ERR2510370/pilon/ERR2510370.vcf'
Traceback (most recent call last):
  File "/home/kin672/anaconda3/envs/jupytervenv/bin/fast-lineage-caller", line 62, in <module>
    lineage_caller_vcf.assign_lineage_from_vcf_snp_counts(name_file, args.input_file, d[0], d[1], d[2], d[3], print_header, args.out, keep_red, pass_filter)
  File "/home/kin672/anaconda3/envs/jupytervenv/lib/python3.10/site-packages/fast_lineage_caller/lineage_caller_vcf.py", line 65, in assign_lineage_from_vcf_snp_counts
    with open(vcf, "r") as inp:
FileNotFoundError: [Errno 2] No such file or directory: '/n/data1/hms/dbmi/farhat/rollingDB/cryptic_output/ERR2510339/pilon/ERR2510339.vcf'
Traceback (most recent call last):
  File "/home/kin672/anaconda3/envs/jupytervenv/bin/fast-lineage-caller", line 62, in <module>
    lineage_caller_vcf.assign_lineage_from_vcf_snp_counts(name_file, args.input_file, d[0], d[1], d[2], d[3], print_header, args.out, keep_red, pass_filter)
  File "/home/kin672/anaconda3/envs/jupytervenv/lib/python3.10/site-packages/fast_lineage_caller/lineage_caller_vcf.py", line 65, in assign_lineage_from_vcf_snp_counts
    with open(vcf, "r") as inp:
FileNotFoundError: [Errno 2] No such file or directory: '/n/data1/hms/dbmi/farhat/rollingDB/cryptic_output/ERR2510298/pilon/ERR2510298.vcf'
Traceback (most recent call last):
  File "/home/kin672/anaconda3/envs/jupytervenv/bin/fast-lineage-caller", line 62, in <module>
    lineage_caller_vcf.assign_lineage_from_vcf_snp_counts(name_file, args.input_file, d[0], d[1], d[2], d[3], print_header, args.out, keep_red, pass_filter)
  File "/home/kin672/anaconda3/envs/jupytervenv/lib/python3.10/site-packages/fast_lineage_caller/lineage_caller_vcf.py", line 65, in assign_lineage_from_vcf_snp_counts
    with open(vcf, "r") as inp:
FileNotFoundError: [Errno 2] No such file or directory: '/n/data1/hms/dbmi/farhat/rollingDB/cryptic_output/ERR2510289/pilon/ERR2510289.vcf'
Traceback (most recent call last):
  File "/home/kin672/anaconda3/envs/jupytervenv/bin/fast-lineage-caller", line 62, in <module>
    lineage_caller_vcf.assign_lineage_from_vcf_snp_counts(name_file, args.input_file, d[0], d[1], d[2], d[3], print_header, args.out, keep_red, pass_filter)
  File "/home/kin672/anaconda3/envs/jupytervenv/lib/python3.10/site-packages/fast_lineage_caller/lineage_caller_vcf.py", line 65, in assign_lineage_from_vcf_snp_counts
    with open(vcf, "r") as inp:
FileNotFoundError: [Errno 2] No such file or directory: '/n/data1/hms/dbmi/farhat/rollingDB/cryptic_output/ERR2510258/pilon/ERR2510258.vcf'
Traceback (most recent call last):
  File "/home/kin672/anaconda3/envs/jupytervenv/bin/fast-lineage-caller", line 62, in <module>
    lineage_caller_vcf.assign_lineage_from_vcf_snp_counts(name_file, args.input_file, d[0], d[1], d[2], d[3], print_header, args.out, keep_red, pass_filter)
  File "/home/kin672/anaconda3/envs/jupytervenv/lib/python3.10/site-packages/fast_lineage_caller/lineage_caller_vcf.py", line 65, in assign_lineage_from_vcf_snp_counts
    with open(vcf, "r") as inp:
FileNotFoundError: [Errno 2] No such file or directory: '/n/data1/hms/dbmi/farhat/rollingDB/genomic_data/SAMEA104394708/pilon/SAMEA104394708.vcf'
Traceback (most recent call last):
  File "/home/kin672/anaconda3/envs/jupytervenv/bin/fast-lineage-caller", line 62, in <module>
    lineage_caller_vcf.assign_lineage_from_vcf_snp_counts(name_file, args.input_file, d[0], d[1], d[2], d[3], print_header, args.out, keep_red, pass_filter)
  File "/home/kin672/anaconda3/envs/jupytervenv/lib/python3.10/site-packages/fast_lineage_caller/lineage_caller_vcf.py", line 65, in assign_lineage_from_vcf_snp_counts
    with open(vcf, "r") as inp:
FileNotFoundError: [Errno 2] No such file or directory: '/n/data1/hms/dbmi/farhat/rollingDB/genomic_data/SAMEA104394701/pilon/SAMEA104394701.vcf'
Traceback (most recent call last):
  File "/home/kin672/anaconda3/envs/jupytervenv/bin/fast-lineage-caller", line 62, in <module>
    lineage_caller_vcf.assign_lineage_from_vcf_snp_counts(name_file, args.input_file, d[0], d[1], d[2], d[3], print_header, args.out, keep_red, pass_filter)
  File "/home/kin672/anaconda3/envs/jupytervenv/lib/python3.10/site-packages/fast_lineage_caller/lineage_caller_vcf.py", line 65, in assign_lineage_from_vcf_snp_counts
    with open(vcf, "r") as inp:
FileNotFoundError: [Errno 2] No such file or directory: '/n/data1/hms/dbmi/farhat/rollingDB/genomic_data/SAMEA104394653/pilon/SAMEA104394653.vcf'
Traceback (most recent call last):
  File "/home/kin672/anaconda3/envs/jupytervenv/bin/fast-lineage-caller", line 62, in <module>
    lineage_caller_vcf.assign_lineage_from_vcf_snp_counts(name_file, args.input_file, d[0], d[1], d[2], d[3], print_header, args.out, keep_red, pass_filter)
  File "/home/kin672/anaconda3/envs/jupytervenv/lib/python3.10/site-packages/fast_lineage_caller/lineage_caller_vcf.py", line 65, in assign_lineage_from_vcf_snp_counts
    with open(vcf, "r") as inp:
FileNotFoundError: [Errno 2] No such file or directory: '/n/data1/hms/dbmi/farhat/rollingDB/genomic_data/SAMEA104394650/pilon/SAMEA104394650.vcf'
Traceback (most recent call last):
  File "/home/kin672/anaconda3/envs/jupytervenv/bin/fast-lineage-caller", line 62, in <module>
    lineage_caller_vcf.assign_lineage_from_vcf_snp_counts(name_file, args.input_file, d[0], d[1], d[2], d[3], print_header, args.out, keep_red, pass_filter)
  File "/home/kin672/anaconda3/envs/jupytervenv/lib/python3.10/site-packages/fast_lineage_caller/lineage_caller_vcf.py", line 65, in assign_lineage_from_vcf_snp_counts
    with open(vcf, "r") as inp:
FileNotFoundError: [Errno 2] No such file or directory: '/n/data1/hms/dbmi/farhat/rollingDB/genomic_data/SAMEA104394619/pilon/SAMEA104394619.vcf'
Traceback (most recent call last):
  File "/home/kin672/anaconda3/envs/jupytervenv/bin/fast-lineage-caller", line 62, in <module>
    lineage_caller_vcf.assign_lineage_from_vcf_snp_counts(name_file, args.input_file, d[0], d[1], d[2], d[3], print_header, args.out, keep_red, pass_filter)
  File "/home/kin672/anaconda3/envs/jupytervenv/lib/python3.10/site-packages/fast_lineage_caller/lineage_caller_vcf.py", line 65, in assign_lineage_from_vcf_snp_counts
    with open(vcf, "r") as inp:
FileNotFoundError: [Errno 2] No such file or directory: '/n/data1/hms/dbmi/farhat/rollingDB/genomic_data/SAMEA104394505/pilon/SAMEA104394505.vcf'
Traceback (most recent call last):
  File "/home/kin672/anaconda3/envs/jupytervenv/bin/fast-lineage-caller", line 62, in <module>
    lineage_caller_vcf.assign_lineage_from_vcf_snp_counts(name_file, args.input_file, d[0], d[1], d[2], d[3], print_header, args.out, keep_red, pass_filter)
  File "/home/kin672/anaconda3/envs/jupytervenv/lib/python3.10/site-packages/fast_lineage_caller/lineage_caller_vcf.py", line 65, in assign_lineage_from_vcf_snp_counts
    with open(vcf, "r") as inp:
FileNotFoundError: [Errno 2] No such file or directory: '/n/data1/hms/dbmi/farhat/rollingDB/genomic_data/SAMEA104394492/pilon/SAMEA104394492.vcf'
Traceback (most recent call last):
  File "/home/kin672/anaconda3/envs/jupytervenv/bin/fast-lineage-caller", line 62, in <module>
    lineage_caller_vcf.assign_lineage_from_vcf_snp_counts(name_file, args.input_file, d[0], d[1], d[2], d[3], print_header, args.out, keep_red, pass_filter)
  File "/home/kin672/anaconda3/envs/jupytervenv/lib/python3.10/site-packages/fast_lineage_caller/lineage_caller_vcf.py", line 65, in assign_lineage_from_vcf_snp_counts
    with open(vcf, "r") as inp:
FileNotFoundError: [Errno 2] No such file or directory: '/n/data1/hms/dbmi/farhat/rollingDB/genomic_data/SAMEA104394490/pilon/SAMEA104394490.vcf'
Traceback (most recent call last):
  File "/home/kin672/anaconda3/envs/jupytervenv/bin/fast-lineage-caller", line 62, in <module>
    lineage_caller_vcf.assign_lineage_from_vcf_snp_counts(name_file, args.input_file, d[0], d[1], d[2], d[3], print_header, args.out, keep_red, pass_filter)
  File "/home/kin672/anaconda3/envs/jupytervenv/lib/python3.10/site-packages/fast_lineage_caller/lineage_caller_vcf.py", line 65, in assign_lineage_from_vcf_snp_counts
    with open(vcf, "r") as inp:
FileNotFoundError: [Errno 2] No such file or directory: '/n/data1/hms/dbmi/farhat/rollingDB/genomic_data/SAMEA104394489/pilon/SAMEA104394489.vcf'
Traceback (most recent call last):
  File "/home/kin672/anaconda3/envs/jupytervenv/bin/fast-lineage-caller", line 62, in <module>
    lineage_caller_vcf.assign_lineage_from_vcf_snp_counts(name_file, args.input_file, d[0], d[1], d[2], d[3], print_header, args.out, keep_red, pass_filter)
  File "/home/kin672/anaconda3/envs/jupytervenv/lib/python3.10/site-packages/fast_lineage_caller/lineage_caller_vcf.py", line 65, in assign_lineage_from_vcf_snp_counts
    with open(vcf, "r") as inp:
FileNotFoundError: [Errno 2] No such file or directory: '/n/data1/hms/dbmi/farhat/rollingDB/genomic_data/SAMEA104394483/pilon/SAMEA104394483.vcf'
Traceback (most recent call last):
  File "/home/kin672/anaconda3/envs/jupytervenv/bin/fast-lineage-caller", line 62, in <module>
    lineage_caller_vcf.assign_lineage_from_vcf_snp_counts(name_file, args.input_file, d[0], d[1], d[2], d[3], print_header, args.out, keep_red, pass_filter)
  File "/home/kin672/anaconda3/envs/jupytervenv/lib/python3.10/site-packages/fast_lineage_caller/lineage_caller_vcf.py", line 65, in assign_lineage_from_vcf_snp_counts
    with open(vcf, "r") as inp:
FileNotFoundError: [Errno 2] No such file or directory: '/n/data1/hms/dbmi/farhat/rollingDB/genomic_data/SAMEA104394469/pilon/SAMEA104394469.vcf'
Traceback (most recent call last):
  File "/home/kin672/anaconda3/envs/jupytervenv/bin/fast-lineage-caller", line 62, in <module>
    lineage_caller_vcf.assign_lineage_from_vcf_snp_counts(name_file, args.input_file, d[0], d[1], d[2], d[3], print_header, args.out, keep_red, pass_filter)
  File "/home/kin672/anaconda3/envs/jupytervenv/lib/python3.10/site-packages/fast_lineage_caller/lineage_caller_vcf.py", line 65, in assign_lineage_from_vcf_snp_counts
    with open(vcf, "r") as inp:
FileNotFoundError: [Errno 2] No such file or directory: '/n/data1/hms/dbmi/farhat/rollingDB/genomic_data/SAMEA104394428/pilon/SAMEA104394428.vcf'
Traceback (most recent call last):
  File "/home/kin672/anaconda3/envs/jupytervenv/bin/fast-lineage-caller", line 62, in <module>
    lineage_caller_vcf.assign_lineage_from_vcf_snp_counts(name_file, args.input_file, d[0], d[1], d[2], d[3], print_header, args.out, keep_red, pass_filter)
  File "/home/kin672/anaconda3/envs/jupytervenv/lib/python3.10/site-packages/fast_lineage_caller/lineage_caller_vcf.py", line 65, in assign_lineage_from_vcf_snp_counts
    with open(vcf, "r") as inp:
FileNotFoundError: [Errno 2] No such file or directory: '/n/data1/hms/dbmi/farhat/rollingDB/genomic_data/SAMEA104394404/pilon/SAMEA104394404.vcf'
Traceback (most recent call last):
  File "/home/kin672/anaconda3/envs/jupytervenv/bin/fast-lineage-caller", line 62, in <module>
    lineage_caller_vcf.assign_lineage_from_vcf_snp_counts(name_file, args.input_file, d[0], d[1], d[2], d[3], print_header, args.out, keep_red, pass_filter)
  File "/home/kin672/anaconda3/envs/jupytervenv/lib/python3.10/site-packages/fast_lineage_caller/lineage_caller_vcf.py", line 65, in assign_lineage_from_vcf_snp_counts
    with open(vcf, "r") as inp:
FileNotFoundError: [Errno 2] No such file or directory: '/n/data1/hms/dbmi/farhat/rollingDB/genomic_data/SAMEA104394396/pilon/SAMEA104394396.vcf'
Traceback (most recent call last):
  File "/home/kin672/anaconda3/envs/jupytervenv/bin/fast-lineage-caller", line 62, in <module>
    lineage_caller_vcf.assign_lineage_from_vcf_snp_counts(name_file, args.input_file, d[0], d[1], d[2], d[3], print_header, args.out, keep_red, pass_filter)
  File "/home/kin672/anaconda3/envs/jupytervenv/lib/python3.10/site-packages/fast_lineage_caller/lineage_caller_vcf.py", line 65, in assign_lineage_from_vcf_snp_counts
    with open(vcf, "r") as inp:
FileNotFoundError: [Errno 2] No such file or directory: '/n/data1/hms/dbmi/farhat/rollingDB/genomic_data/SAMEA104394386/pilon/SAMEA104394386.vcf'
Traceback (most recent call last):
  File "/home/kin672/anaconda3/envs/jupytervenv/bin/fast-lineage-caller", line 62, in <module>
    lineage_caller_vcf.assign_lineage_from_vcf_snp_counts(name_file, args.input_file, d[0], d[1], d[2], d[3], print_header, args.out, keep_red, pass_filter)
  File "/home/kin672/anaconda3/envs/jupytervenv/lib/python3.10/site-packages/fast_lineage_caller/lineage_caller_vcf.py", line 65, in assign_lineage_from_vcf_snp_counts
    with open(vcf, "r") as inp:
FileNotFoundError: [Errno 2] No such file or directory: '/n/data1/hms/dbmi/farhat/rollingDB/genomic_data/SAMEA104172515/pilon/SAMEA104172515.vcf'
Traceback (most recent call last):
  File "/home/kin672/anaconda3/envs/jupytervenv/bin/fast-lineage-caller", line 62, in <module>
    lineage_caller_vcf.assign_lineage_from_vcf_snp_counts(name_file, args.input_file, d[0], d[1], d[2], d[3], print_header, args.out, keep_red, pass_filter)
  File "/home/kin672/anaconda3/envs/jupytervenv/lib/python3.10/site-packages/fast_lineage_caller/lineage_caller_vcf.py", line 65, in assign_lineage_from_vcf_snp_counts
    with open(vcf, "r") as inp:
FileNotFoundError: [Errno 2] No such file or directory: '/n/data1/hms/dbmi/farhat/rollingDB/genomic_data/SAMEA104172502/pilon/SAMEA104172502.vcf'
Traceback (most recent call last):
  File "/home/kin672/anaconda3/envs/jupytervenv/bin/fast-lineage-caller", line 62, in <module>
    lineage_caller_vcf.assign_lineage_from_vcf_snp_counts(name_file, args.input_file, d[0], d[1], d[2], d[3], print_header, args.out, keep_red, pass_filter)
  File "/home/kin672/anaconda3/envs/jupytervenv/lib/python3.10/site-packages/fast_lineage_caller/lineage_caller_vcf.py", line 65, in assign_lineage_from_vcf_snp_counts
    with open(vcf, "r") as inp:
FileNotFoundError: [Errno 2] No such file or directory: '/n/data1/hms/dbmi/farhat/rollingDB/genomic_data/SAMEA104172488/pilon/SAMEA104172488.vcf'
Traceback (most recent call last):
  File "/home/kin672/anaconda3/envs/jupytervenv/bin/fast-lineage-caller", line 62, in <module>
    lineage_caller_vcf.assign_lineage_from_vcf_snp_counts(name_file, args.input_file, d[0], d[1], d[2], d[3], print_header, args.out, keep_red, pass_filter)
  File "/home/kin672/anaconda3/envs/jupytervenv/lib/python3.10/site-packages/fast_lineage_caller/lineage_caller_vcf.py", line 65, in assign_lineage_from_vcf_snp_counts
    with open(vcf, "r") as inp:
FileNotFoundError: [Errno 2] No such file or directory: '/n/data1/hms/dbmi/farhat/rollingDB/genomic_data/SAMEA104172484/pilon/SAMEA104172484.vcf'
Traceback (most recent call last):
  File "/home/kin672/anaconda3/envs/jupytervenv/bin/fast-lineage-caller", line 62, in <module>
    lineage_caller_vcf.assign_lineage_from_vcf_snp_counts(name_file, args.input_file, d[0], d[1], d[2], d[3], print_header, args.out, keep_red, pass_filter)
  File "/home/kin672/anaconda3/envs/jupytervenv/lib/python3.10/site-packages/fast_lineage_caller/lineage_caller_vcf.py", line 65, in assign_lineage_from_vcf_snp_counts
    with open(vcf, "r") as inp:
FileNotFoundError: [Errno 2] No such file or directory: '/n/data1/hms/dbmi/farhat/rollingDB/genomic_data/SAMEA104172481/pilon/SAMEA104172481.vcf'
Traceback (most recent call last):
  File "/home/kin672/anaconda3/envs/jupytervenv/bin/fast-lineage-caller", line 62, in <module>
    lineage_caller_vcf.assign_lineage_from_vcf_snp_counts(name_file, args.input_file, d[0], d[1], d[2], d[3], print_header, args.out, keep_red, pass_filter)
  File "/home/kin672/anaconda3/envs/jupytervenv/lib/python3.10/site-packages/fast_lineage_caller/lineage_caller_vcf.py", line 65, in assign_lineage_from_vcf_snp_counts
    with open(vcf, "r") as inp:
FileNotFoundError: [Errno 2] No such file or directory: '/n/data1/hms/dbmi/farhat/rollingDB/genomic_data/SAMEA104172469/pilon/SAMEA104172469.vcf'
Traceback (most recent call last):
  File "/home/kin672/anaconda3/envs/jupytervenv/bin/fast-lineage-caller", line 62, in <module>
    lineage_caller_vcf.assign_lineage_from_vcf_snp_counts(name_file, args.input_file, d[0], d[1], d[2], d[3], print_header, args.out, keep_red, pass_filter)
  File "/home/kin672/anaconda3/envs/jupytervenv/lib/python3.10/site-packages/fast_lineage_caller/lineage_caller_vcf.py", line 65, in assign_lineage_from_vcf_snp_counts
    with open(vcf, "r") as inp:
FileNotFoundError: [Errno 2] No such file or directory: '/n/data1/hms/dbmi/farhat/rollingDB/genomic_data/SAMEA104172459/pilon/SAMEA104172459.vcf'
Traceback (most recent call last):
  File "/home/kin672/anaconda3/envs/jupytervenv/bin/fast-lineage-caller", line 62, in <module>
    lineage_caller_vcf.assign_lineage_from_vcf_snp_counts(name_file, args.input_file, d[0], d[1], d[2], d[3], print_header, args.out, keep_red, pass_filter)
  File "/home/kin672/anaconda3/envs/jupytervenv/lib/python3.10/site-packages/fast_lineage_caller/lineage_caller_vcf.py", line 65, in assign_lineage_from_vcf_snp_counts
    with open(vcf, "r") as inp:
FileNotFoundError: [Errno 2] No such file or directory: '/n/data1/hms/dbmi/farhat/rollingDB/genomic_data/SAMEA104172458/pilon/SAMEA104172458.vcf'
Traceback (most recent call last):
  File "/home/kin672/anaconda3/envs/jupytervenv/bin/fast-lineage-caller", line 62, in <module>
    lineage_caller_vcf.assign_lineage_from_vcf_snp_counts(name_file, args.input_file, d[0], d[1], d[2], d[3], print_header, args.out, keep_red, pass_filter)
  File "/home/kin672/anaconda3/envs/jupytervenv/lib/python3.10/site-packages/fast_lineage_caller/lineage_caller_vcf.py", line 65, in assign_lineage_from_vcf_snp_counts
    with open(vcf, "r") as inp:
FileNotFoundError: [Errno 2] No such file or directory: '/n/data1/hms/dbmi/farhat/rollingDB/genomic_data/SAMEA104172443/pilon/SAMEA104172443.vcf'
Traceback (most recent call last):
  File "/home/kin672/anaconda3/envs/jupytervenv/bin/fast-lineage-caller", line 62, in <module>
    lineage_caller_vcf.assign_lineage_from_vcf_snp_counts(name_file, args.input_file, d[0], d[1], d[2], d[3], print_header, args.out, keep_red, pass_filter)
  File "/home/kin672/anaconda3/envs/jupytervenv/lib/python3.10/site-packages/fast_lineage_caller/lineage_caller_vcf.py", line 65, in assign_lineage_from_vcf_snp_counts
    with open(vcf, "r") as inp:
FileNotFoundError: [Errno 2] No such file or directory: '/n/data1/hms/dbmi/farhat/rollingDB/genomic_data/SAMEA104172420/pilon/SAMEA104172420.vcf'
Traceback (most recent call last):
  File "/home/kin672/anaconda3/envs/jupytervenv/bin/fast-lineage-caller", line 62, in <module>
    lineage_caller_vcf.assign_lineage_from_vcf_snp_counts(name_file, args.input_file, d[0], d[1], d[2], d[3], print_header, args.out, keep_red, pass_filter)
  File "/home/kin672/anaconda3/envs/jupytervenv/lib/python3.10/site-packages/fast_lineage_caller/lineage_caller_vcf.py", line 65, in assign_lineage_from_vcf_snp_counts
    with open(vcf, "r") as inp:
FileNotFoundError: [Errno 2] No such file or directory: '/n/data1/hms/dbmi/farhat/rollingDB/genomic_data/SAMEA104172419/pilon/SAMEA104172419.vcf'
Traceback (most recent call last):
  File "/home/kin672/anaconda3/envs/jupytervenv/bin/fast-lineage-caller", line 62, in <module>
    lineage_caller_vcf.assign_lineage_from_vcf_snp_counts(name_file, args.input_file, d[0], d[1], d[2], d[3], print_header, args.out, keep_red, pass_filter)
  File "/home/kin672/anaconda3/envs/jupytervenv/lib/python3.10/site-packages/fast_lineage_caller/lineage_caller_vcf.py", line 65, in assign_lineage_from_vcf_snp_counts
    with open(vcf, "r") as inp:
FileNotFoundError: [Errno 2] No such file or directory: '/n/data1/hms/dbmi/farhat/rollingDB/genomic_data/SAMEA104172418/pilon/SAMEA104172418.vcf'
Traceback (most recent call last):
  File "/home/kin672/anaconda3/envs/jupytervenv/bin/fast-lineage-caller", line 62, in <module>
    lineage_caller_vcf.assign_lineage_from_vcf_snp_counts(name_file, args.input_file, d[0], d[1], d[2], d[3], print_header, args.out, keep_red, pass_filter)
  File "/home/kin672/anaconda3/envs/jupytervenv/lib/python3.10/site-packages/fast_lineage_caller/lineage_caller_vcf.py", line 65, in assign_lineage_from_vcf_snp_counts
    with open(vcf, "r") as inp:
FileNotFoundError: [Errno 2] No such file or directory: '/n/data1/hms/dbmi/farhat/rollingDB/genomic_data/SAMEA104172417/pilon/SAMEA104172417.vcf'
