/bin/sh: -c: line 0: syntax error near unexpected token `('
/bin/sh: -c: line 0: `/home/kin672/anaconda3/envs/jupytervenv/bin/fast-lineage-caller //n//groups//gentb_www//predictData//tbdata_00000835//TSVC_variants_IonXpress_017 (2).vcf --noheader --count'
usage: fast-lineage-caller [-h] [--out OUT] [--noheader] [--scheme SCHEME] [--keep] [--count] [--pass] input_file
fast-lineage-caller: error: unrecognized arguments: No 3211379_IonXpress_021.vcf
Traceback (most recent call last):
  File "/home/kin672/anaconda3/envs/jupytervenv/bin/fast-lineage-caller", line 62, in <module>
    lineage_caller_vcf.assign_lineage_from_vcf_snp_counts(name_file, args.input_file, d[0], d[1], d[2], d[3], print_header, args.out, keep_red, pass_filter)
  File "/home/kin672/anaconda3/envs/jupytervenv/lib/python3.10/site-packages/fast_lineage_caller/lineage_caller_vcf.py", line 65, in assign_lineage_from_vcf_snp_counts
    with open(vcf, "r") as inp:
FileNotFoundError: [Errno 2] No such file or directory: 'Serialsamples.XD00998454.dedup_reads.bam.indelqualed_reads.bam.vars.vcf'
usage: fast-lineage-caller [-h] [--out OUT] [--noheader] [--scheme SCHEME] [--keep] [--count] [--pass] input_file
fast-lineage-caller: error: unrecognized arguments: QC_IonXpress_028.vcf
Traceback (most recent call last):
  File "/home/kin672/anaconda3/envs/jupytervenv/bin/fast-lineage-caller", line 62, in <module>
    lineage_caller_vcf.assign_lineage_from_vcf_snp_counts(name_file, args.input_file, d[0], d[1], d[2], d[3], print_header, args.out, keep_red, pass_filter)
  File "/home/kin672/anaconda3/envs/jupytervenv/lib/python3.10/site-packages/fast_lineage_caller/lineage_caller_vcf.py", line 65, in assign_lineage_from_vcf_snp_counts
    with open(vcf, "r") as inp:
FileNotFoundError: [Errno 2] No such file or directory: 'Serialsamples.XD00428048.dedup_reads.bam.indelqualed_reads.bam.vars.vcf'
usage: fast-lineage-caller [-h] [--out OUT] [--noheader] [--scheme SCHEME] [--keep] [--count] [--pass] input_file
fast-lineage-caller: error: unrecognized arguments: No 321528_IonXpress_018.vcf
usage: fast-lineage-caller [-h] [--out OUT] [--noheader] [--scheme SCHEME] [--keep] [--count] [--pass] input_file
fast-lineage-caller: error: unrecognized arguments: No 321262_ionXpress_017.vcf
Traceback (most recent call last):
  File "/home/kin672/anaconda3/envs/jupytervenv/bin/fast-lineage-caller", line 62, in <module>
    lineage_caller_vcf.assign_lineage_from_vcf_snp_counts(name_file, args.input_file, d[0], d[1], d[2], d[3], print_header, args.out, keep_red, pass_filter)
  File "/home/kin672/anaconda3/envs/jupytervenv/lib/python3.10/site-packages/fast_lineage_caller/lineage_caller_vcf.py", line 65, in assign_lineage_from_vcf_snp_counts
    with open(vcf, "r") as inp:
FileNotFoundError: [Errno 2] No such file or directory: 'Serialsamples.XD00922398.dedup_reads.bam.indelqualed_reads.bam.vars.vcf'
usage: fast-lineage-caller [-h] [--out OUT] [--noheader] [--scheme SCHEME] [--keep] [--count] [--pass] input_file
fast-lineage-caller: error: unrecognized arguments: No 3211380_IonXpress_022.vcf
Traceback (most recent call last):
  File "/home/kin672/anaconda3/envs/jupytervenv/bin/fast-lineage-caller", line 62, in <module>
    lineage_caller_vcf.assign_lineage_from_vcf_snp_counts(name_file, args.input_file, d[0], d[1], d[2], d[3], print_header, args.out, keep_red, pass_filter)
  File "/home/kin672/anaconda3/envs/jupytervenv/lib/python3.10/site-packages/fast_lineage_caller/lineage_caller_vcf.py", line 65, in assign_lineage_from_vcf_snp_counts
    with open(vcf, "r") as inp:
FileNotFoundError: [Errno 2] No such file or directory: 'TB-444-213-19_S94_R.all.vcf'
Traceback (most recent call last):
  File "/home/kin672/anaconda3/envs/jupytervenv/bin/fast-lineage-caller", line 62, in <module>
    lineage_caller_vcf.assign_lineage_from_vcf_snp_counts(name_file, args.input_file, d[0], d[1], d[2], d[3], print_header, args.out, keep_red, pass_filter)
  File "/home/kin672/anaconda3/envs/jupytervenv/lib/python3.10/site-packages/fast_lineage_caller/lineage_caller_vcf.py", line 65, in assign_lineage_from_vcf_snp_counts
    with open(vcf, "r") as inp:
FileNotFoundError: [Errno 2] No such file or directory: 'TB-444-80-19_S256_R.all.vcf'
usage: fast-lineage-caller [-h] [--out OUT] [--noheader] [--scheme SCHEME] [--keep] [--count] [--pass] input_file
fast-lineage-caller: error: unrecognized arguments: No 3211198_IonXpress_020.vcf
Traceback (most recent call last):
  File "/home/kin672/anaconda3/envs/jupytervenv/bin/fast-lineage-caller", line 62, in <module>
    lineage_caller_vcf.assign_lineage_from_vcf_snp_counts(name_file, args.input_file, d[0], d[1], d[2], d[3], print_header, args.out, keep_red, pass_filter)
  File "/home/kin672/anaconda3/envs/jupytervenv/lib/python3.10/site-packages/fast_lineage_caller/lineage_caller_vcf.py", line 65, in assign_lineage_from_vcf_snp_counts
    with open(vcf, "r") as inp:
FileNotFoundError: [Errno 2] No such file or directory: 'Serialsamples.XD00481853.dedup_reads.bam.indelqualed_reads.bam.vars.vcf'
usage: fast-lineage-caller [-h] [--out OUT] [--noheader] [--scheme SCHEME] [--keep] [--count] [--pass] input_file
fast-lineage-caller: error: unrecognized arguments: No 321769_IonXpress_019.vcf
usage: fast-lineage-caller [-h] [--out OUT] [--noheader] [--scheme SCHEME] [--keep] [--count] [--pass] input_file
fast-lineage-caller: error: unrecognized arguments: No 3212401_IonXpress_023.vcf
usage: fast-lineage-caller [-h] [--out OUT] [--noheader] [--scheme SCHEME] [--keep] [--count] [--pass] input_file
fast-lineage-caller: error: unrecognized arguments: No 3213465_IonXpress_024.vcf
/bin/sh: -c: line 0: syntax error near unexpected token `('
/bin/sh: -c: line 0: `/home/kin672/anaconda3/envs/jupytervenv/bin/fast-lineage-caller //n//groups//gentb_www//predictData//tbdata_00000993//TSVC_variants_IonXpress_017 (3).vcf --noheader --count'
Traceback (most recent call last):
  File "/home/kin672/anaconda3/envs/jupytervenv/bin/fast-lineage-caller", line 62, in <module>
    lineage_caller_vcf.assign_lineage_from_vcf_snp_counts(name_file, args.input_file, d[0], d[1], d[2], d[3], print_header, args.out, keep_red, pass_filter)
  File "/home/kin672/anaconda3/envs/jupytervenv/lib/python3.10/site-packages/fast_lineage_caller/lineage_caller_vcf.py", line 65, in assign_lineage_from_vcf_snp_counts
    with open(vcf, "r") as inp:
FileNotFoundError: [Errno 2] No such file or directory: 'BORA_4.vcf'
Traceback (most recent call last):
  File "/home/kin672/anaconda3/envs/jupytervenv/bin/fast-lineage-caller", line 62, in <module>
    lineage_caller_vcf.assign_lineage_from_vcf_snp_counts(name_file, args.input_file, d[0], d[1], d[2], d[3], print_header, args.out, keep_red, pass_filter)
  File "/home/kin672/anaconda3/envs/jupytervenv/lib/python3.10/site-packages/fast_lineage_caller/lineage_caller_vcf.py", line 65, in assign_lineage_from_vcf_snp_counts
    with open(vcf, "r") as inp:
FileNotFoundError: [Errno 2] No such file or directory: 'BORA_6.vcf'
Traceback (most recent call last):
  File "/home/kin672/anaconda3/envs/jupytervenv/bin/fast-lineage-caller", line 62, in <module>
    lineage_caller_vcf.assign_lineage_from_vcf_snp_counts(name_file, args.input_file, d[0], d[1], d[2], d[3], print_header, args.out, keep_red, pass_filter)
  File "/home/kin672/anaconda3/envs/jupytervenv/lib/python3.10/site-packages/fast_lineage_caller/lineage_caller_vcf.py", line 65, in assign_lineage_from_vcf_snp_counts
    with open(vcf, "r") as inp:
FileNotFoundError: [Errno 2] No such file or directory: 'Serialsamples.XD00946217.dedup_reads.bam.indelqualed_reads.bam.vars.vcf'
Traceback (most recent call last):
  File "/home/kin672/anaconda3/envs/jupytervenv/bin/fast-lineage-caller", line 62, in <module>
    lineage_caller_vcf.assign_lineage_from_vcf_snp_counts(name_file, args.input_file, d[0], d[1], d[2], d[3], print_header, args.out, keep_red, pass_filter)
  File "/home/kin672/anaconda3/envs/jupytervenv/lib/python3.10/site-packages/fast_lineage_caller/lineage_caller_vcf.py", line 65, in assign_lineage_from_vcf_snp_counts
    with open(vcf, "r") as inp:
FileNotFoundError: [Errno 2] No such file or directory: 'BORA_14.vcf'
Traceback (most recent call last):
  File "/home/kin672/anaconda3/envs/jupytervenv/bin/fast-lineage-caller", line 62, in <module>
    lineage_caller_vcf.assign_lineage_from_vcf_snp_counts(name_file, args.input_file, d[0], d[1], d[2], d[3], print_header, args.out, keep_red, pass_filter)
  File "/home/kin672/anaconda3/envs/jupytervenv/lib/python3.10/site-packages/fast_lineage_caller/lineage_caller_vcf.py", line 65, in assign_lineage_from_vcf_snp_counts
    with open(vcf, "r") as inp:
FileNotFoundError: [Errno 2] No such file or directory: 'BORA_18.vcf'
Traceback (most recent call last):
  File "/home/kin672/anaconda3/envs/jupytervenv/bin/fast-lineage-caller", line 62, in <module>
    lineage_caller_vcf.assign_lineage_from_vcf_snp_counts(name_file, args.input_file, d[0], d[1], d[2], d[3], print_header, args.out, keep_red, pass_filter)
  File "/home/kin672/anaconda3/envs/jupytervenv/lib/python3.10/site-packages/fast_lineage_caller/lineage_caller_vcf.py", line 65, in assign_lineage_from_vcf_snp_counts
    with open(vcf, "r") as inp:
FileNotFoundError: [Errno 2] No such file or directory: 'BORA_15.vcf'
Traceback (most recent call last):
  File "/home/kin672/anaconda3/envs/jupytervenv/bin/fast-lineage-caller", line 62, in <module>
    lineage_caller_vcf.assign_lineage_from_vcf_snp_counts(name_file, args.input_file, d[0], d[1], d[2], d[3], print_header, args.out, keep_red, pass_filter)
  File "/home/kin672/anaconda3/envs/jupytervenv/lib/python3.10/site-packages/fast_lineage_caller/lineage_caller_vcf.py", line 65, in assign_lineage_from_vcf_snp_counts
    with open(vcf, "r") as inp:
FileNotFoundError: [Errno 2] No such file or directory: 'BORA_16.vcf'
Traceback (most recent call last):
  File "/home/kin672/anaconda3/envs/jupytervenv/bin/fast-lineage-caller", line 62, in <module>
    lineage_caller_vcf.assign_lineage_from_vcf_snp_counts(name_file, args.input_file, d[0], d[1], d[2], d[3], print_header, args.out, keep_red, pass_filter)
  File "/home/kin672/anaconda3/envs/jupytervenv/lib/python3.10/site-packages/fast_lineage_caller/lineage_caller_vcf.py", line 65, in assign_lineage_from_vcf_snp_counts
    with open(vcf, "r") as inp:
FileNotFoundError: [Errno 2] No such file or directory: 'Serialsamples.XD00934751.dedup_reads.bam.indelqualed_reads.bam.vars.vcf'
Traceback (most recent call last):
  File "/home/kin672/anaconda3/envs/jupytervenv/bin/fast-lineage-caller", line 62, in <module>
    lineage_caller_vcf.assign_lineage_from_vcf_snp_counts(name_file, args.input_file, d[0], d[1], d[2], d[3], print_header, args.out, keep_red, pass_filter)
  File "/home/kin672/anaconda3/envs/jupytervenv/lib/python3.10/site-packages/fast_lineage_caller/lineage_caller_vcf.py", line 65, in assign_lineage_from_vcf_snp_counts
    with open(vcf, "r") as inp:
FileNotFoundError: [Errno 2] No such file or directory: 'Serialsamples.XD00944188.dedup_reads.bam.indelqualed_reads.bam.vars.vcf'
Traceback (most recent call last):
  File "/home/kin672/anaconda3/envs/jupytervenv/bin/fast-lineage-caller", line 62, in <module>
    lineage_caller_vcf.assign_lineage_from_vcf_snp_counts(name_file, args.input_file, d[0], d[1], d[2], d[3], print_header, args.out, keep_red, pass_filter)
  File "/home/kin672/anaconda3/envs/jupytervenv/lib/python3.10/site-packages/fast_lineage_caller/lineage_caller_vcf.py", line 65, in assign_lineage_from_vcf_snp_counts
    with open(vcf, "r") as inp:
FileNotFoundError: [Errno 2] No such file or directory: 'BORA_27.vcf'
Traceback (most recent call last):
  File "/home/kin672/anaconda3/envs/jupytervenv/bin/fast-lineage-caller", line 62, in <module>
    lineage_caller_vcf.assign_lineage_from_vcf_snp_counts(name_file, args.input_file, d[0], d[1], d[2], d[3], print_header, args.out, keep_red, pass_filter)
  File "/home/kin672/anaconda3/envs/jupytervenv/lib/python3.10/site-packages/fast_lineage_caller/lineage_caller_vcf.py", line 65, in assign_lineage_from_vcf_snp_counts
    with open(vcf, "r") as inp:
FileNotFoundError: [Errno 2] No such file or directory: 'BORA_24.vcf'
Traceback (most recent call last):
  File "/home/kin672/anaconda3/envs/jupytervenv/bin/fast-lineage-caller", line 62, in <module>
    lineage_caller_vcf.assign_lineage_from_vcf_snp_counts(name_file, args.input_file, d[0], d[1], d[2], d[3], print_header, args.out, keep_red, pass_filter)
  File "/home/kin672/anaconda3/envs/jupytervenv/lib/python3.10/site-packages/fast_lineage_caller/lineage_caller_vcf.py", line 65, in assign_lineage_from_vcf_snp_counts
    with open(vcf, "r") as inp:
FileNotFoundError: [Errno 2] No such file or directory: 'BORA_26.vcf'
Traceback (most recent call last):
  File "/home/kin672/anaconda3/envs/jupytervenv/bin/fast-lineage-caller", line 62, in <module>
    lineage_caller_vcf.assign_lineage_from_vcf_snp_counts(name_file, args.input_file, d[0], d[1], d[2], d[3], print_header, args.out, keep_red, pass_filter)
  File "/home/kin672/anaconda3/envs/jupytervenv/lib/python3.10/site-packages/fast_lineage_caller/lineage_caller_vcf.py", line 65, in assign_lineage_from_vcf_snp_counts
    with open(vcf, "r") as inp:
FileNotFoundError: [Errno 2] No such file or directory: 'BORA_23.vcf'
Traceback (most recent call last):
  File "/home/kin672/anaconda3/envs/jupytervenv/bin/fast-lineage-caller", line 62, in <module>
    lineage_caller_vcf.assign_lineage_from_vcf_snp_counts(name_file, args.input_file, d[0], d[1], d[2], d[3], print_header, args.out, keep_red, pass_filter)
  File "/home/kin672/anaconda3/envs/jupytervenv/lib/python3.10/site-packages/fast_lineage_caller/lineage_caller_vcf.py", line 65, in assign_lineage_from_vcf_snp_counts
    with open(vcf, "r") as inp:
FileNotFoundError: [Errno 2] No such file or directory: 'BORA_22.vcf'
Traceback (most recent call last):
  File "/home/kin672/anaconda3/envs/jupytervenv/bin/fast-lineage-caller", line 62, in <module>
    lineage_caller_vcf.assign_lineage_from_vcf_snp_counts(name_file, args.input_file, d[0], d[1], d[2], d[3], print_header, args.out, keep_red, pass_filter)
  File "/home/kin672/anaconda3/envs/jupytervenv/lib/python3.10/site-packages/fast_lineage_caller/lineage_caller_vcf.py", line 65, in assign_lineage_from_vcf_snp_counts
    with open(vcf, "r") as inp:
FileNotFoundError: [Errno 2] No such file or directory: 'BORA_30.vcf'
Traceback (most recent call last):
  File "/home/kin672/anaconda3/envs/jupytervenv/bin/fast-lineage-caller", line 62, in <module>
    lineage_caller_vcf.assign_lineage_from_vcf_snp_counts(name_file, args.input_file, d[0], d[1], d[2], d[3], print_header, args.out, keep_red, pass_filter)
  File "/home/kin672/anaconda3/envs/jupytervenv/lib/python3.10/site-packages/fast_lineage_caller/lineage_caller_vcf.py", line 65, in assign_lineage_from_vcf_snp_counts
    with open(vcf, "r") as inp:
FileNotFoundError: [Errno 2] No such file or directory: 'BORA_21.vcf'
Traceback (most recent call last):
  File "/home/kin672/anaconda3/envs/jupytervenv/bin/fast-lineage-caller", line 62, in <module>
    lineage_caller_vcf.assign_lineage_from_vcf_snp_counts(name_file, args.input_file, d[0], d[1], d[2], d[3], print_header, args.out, keep_red, pass_filter)
  File "/home/kin672/anaconda3/envs/jupytervenv/lib/python3.10/site-packages/fast_lineage_caller/lineage_caller_vcf.py", line 65, in assign_lineage_from_vcf_snp_counts
    with open(vcf, "r") as inp:
FileNotFoundError: [Errno 2] No such file or directory: 'BORA_28.vcf'
Traceback (most recent call last):
  File "/home/kin672/anaconda3/envs/jupytervenv/bin/fast-lineage-caller", line 62, in <module>
    lineage_caller_vcf.assign_lineage_from_vcf_snp_counts(name_file, args.input_file, d[0], d[1], d[2], d[3], print_header, args.out, keep_red, pass_filter)
  File "/home/kin672/anaconda3/envs/jupytervenv/lib/python3.10/site-packages/fast_lineage_caller/lineage_caller_vcf.py", line 65, in assign_lineage_from_vcf_snp_counts
    with open(vcf, "r") as inp:
FileNotFoundError: [Errno 2] No such file or directory: 'BORA_29.vcf'
Traceback (most recent call last):
  File "/home/kin672/anaconda3/envs/jupytervenv/bin/fast-lineage-caller", line 62, in <module>
    lineage_caller_vcf.assign_lineage_from_vcf_snp_counts(name_file, args.input_file, d[0], d[1], d[2], d[3], print_header, args.out, keep_red, pass_filter)
  File "/home/kin672/anaconda3/envs/jupytervenv/lib/python3.10/site-packages/fast_lineage_caller/lineage_caller_vcf.py", line 65, in assign_lineage_from_vcf_snp_counts
    with open(vcf, "r") as inp:
FileNotFoundError: [Errno 2] No such file or directory: 'BORA_38.vcf'
Traceback (most recent call last):
  File "/home/kin672/anaconda3/envs/jupytervenv/bin/fast-lineage-caller", line 62, in <module>
    lineage_caller_vcf.assign_lineage_from_vcf_snp_counts(name_file, args.input_file, d[0], d[1], d[2], d[3], print_header, args.out, keep_red, pass_filter)
  File "/home/kin672/anaconda3/envs/jupytervenv/lib/python3.10/site-packages/fast_lineage_caller/lineage_caller_vcf.py", line 65, in assign_lineage_from_vcf_snp_counts
    with open(vcf, "r") as inp:
FileNotFoundError: [Errno 2] No such file or directory: 'BORA_37.vcf'
Traceback (most recent call last):
  File "/home/kin672/anaconda3/envs/jupytervenv/bin/fast-lineage-caller", line 62, in <module>
    lineage_caller_vcf.assign_lineage_from_vcf_snp_counts(name_file, args.input_file, d[0], d[1], d[2], d[3], print_header, args.out, keep_red, pass_filter)
  File "/home/kin672/anaconda3/envs/jupytervenv/lib/python3.10/site-packages/fast_lineage_caller/lineage_caller_vcf.py", line 65, in assign_lineage_from_vcf_snp_counts
    with open(vcf, "r") as inp:
FileNotFoundError: [Errno 2] No such file or directory: 'TB-MoldovaSeq-DNA005-516_S5_ndc.vcf'
Traceback (most recent call last):
  File "/home/kin672/anaconda3/envs/jupytervenv/bin/fast-lineage-caller", line 62, in <module>
    lineage_caller_vcf.assign_lineage_from_vcf_snp_counts(name_file, args.input_file, d[0], d[1], d[2], d[3], print_header, args.out, keep_red, pass_filter)
  File "/home/kin672/anaconda3/envs/jupytervenv/lib/python3.10/site-packages/fast_lineage_caller/lineage_caller_vcf.py", line 65, in assign_lineage_from_vcf_snp_counts
    with open(vcf, "r") as inp:
FileNotFoundError: [Errno 2] No such file or directory: 'TB-MoldovaSeq-DNA0294-4695_S297_ndc.vcf'
Traceback (most recent call last):
  File "/home/kin672/anaconda3/envs/jupytervenv/bin/fast-lineage-caller", line 62, in <module>
    lineage_caller_vcf.assign_lineage_from_vcf_snp_counts(name_file, args.input_file, d[0], d[1], d[2], d[3], print_header, args.out, keep_red, pass_filter)
  File "/home/kin672/anaconda3/envs/jupytervenv/lib/python3.10/site-packages/fast_lineage_caller/lineage_caller_vcf.py", line 65, in assign_lineage_from_vcf_snp_counts
    with open(vcf, "r") as inp:
FileNotFoundError: [Errno 2] No such file or directory: 'TB-MoldovaSeq-DNA0272-3051_S82_ndc.vcf'
Traceback (most recent call last):
  File "/home/kin672/anaconda3/envs/jupytervenv/bin/fast-lineage-caller", line 62, in <module>
    lineage_caller_vcf.assign_lineage_from_vcf_snp_counts(name_file, args.input_file, d[0], d[1], d[2], d[3], print_header, args.out, keep_red, pass_filter)
  File "/home/kin672/anaconda3/envs/jupytervenv/lib/python3.10/site-packages/fast_lineage_caller/lineage_caller_vcf.py", line 65, in assign_lineage_from_vcf_snp_counts
    with open(vcf, "r") as inp:
FileNotFoundError: [Errno 2] No such file or directory: 'TB-MoldovaSeq-DNA0256-4412_S66_ndc.vcf'
Traceback (most recent call last):
  File "/home/kin672/anaconda3/envs/jupytervenv/bin/fast-lineage-caller", line 62, in <module>
    lineage_caller_vcf.assign_lineage_from_vcf_snp_counts(name_file, args.input_file, d[0], d[1], d[2], d[3], print_header, args.out, keep_red, pass_filter)
  File "/home/kin672/anaconda3/envs/jupytervenv/lib/python3.10/site-packages/fast_lineage_caller/lineage_caller_vcf.py", line 65, in assign_lineage_from_vcf_snp_counts
    with open(vcf, "r") as inp:
FileNotFoundError: [Errno 2] No such file or directory: 'TB-MoldovaSeq-DNA093-887_S93_ndc.vcf'
Traceback (most recent call last):
  File "/home/kin672/anaconda3/envs/jupytervenv/bin/fast-lineage-caller", line 62, in <module>
    lineage_caller_vcf.assign_lineage_from_vcf_snp_counts(name_file, args.input_file, d[0], d[1], d[2], d[3], print_header, args.out, keep_red, pass_filter)
  File "/home/kin672/anaconda3/envs/jupytervenv/lib/python3.10/site-packages/fast_lineage_caller/lineage_caller_vcf.py", line 65, in assign_lineage_from_vcf_snp_counts
    with open(vcf, "r") as inp:
FileNotFoundError: [Errno 2] No such file or directory: 'TB-MoldovaSeq-DNA0330-5305_S333_ndc.vcf'
Traceback (most recent call last):
  File "/home/kin672/anaconda3/envs/jupytervenv/bin/fast-lineage-caller", line 62, in <module>
    lineage_caller_vcf.assign_lineage_from_vcf_snp_counts(name_file, args.input_file, d[0], d[1], d[2], d[3], print_header, args.out, keep_red, pass_filter)
  File "/home/kin672/anaconda3/envs/jupytervenv/lib/python3.10/site-packages/fast_lineage_caller/lineage_caller_vcf.py", line 65, in assign_lineage_from_vcf_snp_counts
    with open(vcf, "r") as inp:
FileNotFoundError: [Errno 2] No such file or directory: 'TB-MoldovaSeq-DNA0310-3312_S313_ndc.vcf'
Traceback (most recent call last):
  File "/home/kin672/anaconda3/envs/jupytervenv/bin/fast-lineage-caller", line 62, in <module>
    lineage_caller_vcf.assign_lineage_from_vcf_snp_counts(name_file, args.input_file, d[0], d[1], d[2], d[3], print_header, args.out, keep_red, pass_filter)
  File "/home/kin672/anaconda3/envs/jupytervenv/lib/python3.10/site-packages/fast_lineage_caller/lineage_caller_vcf.py", line 65, in assign_lineage_from_vcf_snp_counts
    with open(vcf, "r") as inp:
FileNotFoundError: [Errno 2] No such file or directory: 'TB-MoldovaSeq-DNA0295-1229_S298_ndc.vcf'
Traceback (most recent call last):
  File "/home/kin672/anaconda3/envs/jupytervenv/bin/fast-lineage-caller", line 62, in <module>
    lineage_caller_vcf.assign_lineage_from_vcf_snp_counts(name_file, args.input_file, d[0], d[1], d[2], d[3], print_header, args.out, keep_red, pass_filter)
  File "/home/kin672/anaconda3/envs/jupytervenv/lib/python3.10/site-packages/fast_lineage_caller/lineage_caller_vcf.py", line 65, in assign_lineage_from_vcf_snp_counts
    with open(vcf, "r") as inp:
FileNotFoundError: [Errno 2] No such file or directory: 'TB-MoldovaSeq-DNA0299-4999_S302_ndc.vcf'
Traceback (most recent call last):
  File "/home/kin672/anaconda3/envs/jupytervenv/bin/fast-lineage-caller", line 62, in <module>
    lineage_caller_vcf.assign_lineage_from_vcf_snp_counts(name_file, args.input_file, d[0], d[1], d[2], d[3], print_header, args.out, keep_red, pass_filter)
  File "/home/kin672/anaconda3/envs/jupytervenv/lib/python3.10/site-packages/fast_lineage_caller/lineage_caller_vcf.py", line 65, in assign_lineage_from_vcf_snp_counts
    with open(vcf, "r") as inp:
FileNotFoundError: [Errno 2] No such file or directory: 'TB-MoldovaSeq-DNA0223-2292_S33_ndc.vcf'
Traceback (most recent call last):
  File "/home/kin672/anaconda3/envs/jupytervenv/bin/fast-lineage-caller", line 62, in <module>
    lineage_caller_vcf.assign_lineage_from_vcf_snp_counts(name_file, args.input_file, d[0], d[1], d[2], d[3], print_header, args.out, keep_red, pass_filter)
  File "/home/kin672/anaconda3/envs/jupytervenv/lib/python3.10/site-packages/fast_lineage_caller/lineage_caller_vcf.py", line 65, in assign_lineage_from_vcf_snp_counts
    with open(vcf, "r") as inp:
FileNotFoundError: [Errno 2] No such file or directory: 'TB-MoldovaSeq-DNA0194-2350_S4_ndc.vcf'
Traceback (most recent call last):
  File "/home/kin672/anaconda3/envs/jupytervenv/bin/fast-lineage-caller", line 62, in <module>
    lineage_caller_vcf.assign_lineage_from_vcf_snp_counts(name_file, args.input_file, d[0], d[1], d[2], d[3], print_header, args.out, keep_red, pass_filter)
  File "/home/kin672/anaconda3/envs/jupytervenv/lib/python3.10/site-packages/fast_lineage_caller/lineage_caller_vcf.py", line 65, in assign_lineage_from_vcf_snp_counts
    with open(vcf, "r") as inp:
FileNotFoundError: [Errno 2] No such file or directory: 'TB-MoldovaSeq-DNA026-12_S26_ndc.vcf'
Traceback (most recent call last):
  File "/home/kin672/anaconda3/envs/jupytervenv/bin/fast-lineage-caller", line 62, in <module>
    lineage_caller_vcf.assign_lineage_from_vcf_snp_counts(name_file, args.input_file, d[0], d[1], d[2], d[3], print_header, args.out, keep_red, pass_filter)
  File "/home/kin672/anaconda3/envs/jupytervenv/lib/python3.10/site-packages/fast_lineage_caller/lineage_caller_vcf.py", line 65, in assign_lineage_from_vcf_snp_counts
    with open(vcf, "r") as inp:
FileNotFoundError: [Errno 2] No such file or directory: 'TB-MoldovaSeq-DNA057-674_S57_ndc.vcf'
Traceback (most recent call last):
  File "/home/kin672/anaconda3/envs/jupytervenv/bin/fast-lineage-caller", line 62, in <module>
    lineage_caller_vcf.assign_lineage_from_vcf_snp_counts(name_file, args.input_file, d[0], d[1], d[2], d[3], print_header, args.out, keep_red, pass_filter)
  File "/home/kin672/anaconda3/envs/jupytervenv/lib/python3.10/site-packages/fast_lineage_caller/lineage_caller_vcf.py", line 65, in assign_lineage_from_vcf_snp_counts
    with open(vcf, "r") as inp:
FileNotFoundError: [Errno 2] No such file or directory: 'TB-MoldovaSeq-DNA173-2332_S174_ndc.vcf'
Traceback (most recent call last):
  File "/home/kin672/anaconda3/envs/jupytervenv/bin/fast-lineage-caller", line 62, in <module>
    lineage_caller_vcf.assign_lineage_from_vcf_snp_counts(name_file, args.input_file, d[0], d[1], d[2], d[3], print_header, args.out, keep_red, pass_filter)
  File "/home/kin672/anaconda3/envs/jupytervenv/lib/python3.10/site-packages/fast_lineage_caller/lineage_caller_vcf.py", line 65, in assign_lineage_from_vcf_snp_counts
    with open(vcf, "r") as inp:
FileNotFoundError: [Errno 2] No such file or directory: 'TB-MoldovaSeq-DNA0284-4250_S94_ndc.vcf'
Traceback (most recent call last):
  File "/home/kin672/anaconda3/envs/jupytervenv/bin/fast-lineage-caller", line 62, in <module>
    lineage_caller_vcf.assign_lineage_from_vcf_snp_counts(name_file, args.input_file, d[0], d[1], d[2], d[3], print_header, args.out, keep_red, pass_filter)
  File "/home/kin672/anaconda3/envs/jupytervenv/lib/python3.10/site-packages/fast_lineage_caller/lineage_caller_vcf.py", line 65, in assign_lineage_from_vcf_snp_counts
    with open(vcf, "r") as inp:
FileNotFoundError: [Errno 2] No such file or directory: 'TB-MoldovaSeq-DNA0196-1878_S6_ndc.vcf'
Traceback (most recent call last):
  File "/home/kin672/anaconda3/envs/jupytervenv/bin/fast-lineage-caller", line 62, in <module>
    lineage_caller_vcf.assign_lineage_from_vcf_snp_counts(name_file, args.input_file, d[0], d[1], d[2], d[3], print_header, args.out, keep_red, pass_filter)
  File "/home/kin672/anaconda3/envs/jupytervenv/lib/python3.10/site-packages/fast_lineage_caller/lineage_caller_vcf.py", line 65, in assign_lineage_from_vcf_snp_counts
    with open(vcf, "r") as inp:
FileNotFoundError: [Errno 2] No such file or directory: 'TB-MoldovaSeq-DNA0292-4416_S295_ndc.vcf'
Traceback (most recent call last):
  File "/home/kin672/anaconda3/envs/jupytervenv/bin/fast-lineage-caller", line 62, in <module>
    lineage_caller_vcf.assign_lineage_from_vcf_snp_counts(name_file, args.input_file, d[0], d[1], d[2], d[3], print_header, args.out, keep_red, pass_filter)
  File "/home/kin672/anaconda3/envs/jupytervenv/lib/python3.10/site-packages/fast_lineage_caller/lineage_caller_vcf.py", line 65, in assign_lineage_from_vcf_snp_counts
    with open(vcf, "r") as inp:
FileNotFoundError: [Errno 2] No such file or directory: 'TB-MoldovaSeq-DNA0241-2352_S51_ndc.vcf'
Traceback (most recent call last):
  File "/home/kin672/anaconda3/envs/jupytervenv/bin/fast-lineage-caller", line 62, in <module>
    lineage_caller_vcf.assign_lineage_from_vcf_snp_counts(name_file, args.input_file, d[0], d[1], d[2], d[3], print_header, args.out, keep_red, pass_filter)
  File "/home/kin672/anaconda3/envs/jupytervenv/lib/python3.10/site-packages/fast_lineage_caller/lineage_caller_vcf.py", line 65, in assign_lineage_from_vcf_snp_counts
    with open(vcf, "r") as inp:
FileNotFoundError: [Errno 2] No such file or directory: 'TB-MoldovaSeq-DNA0316-4135_S319_ndc.vcf'
Traceback (most recent call last):
  File "/home/kin672/anaconda3/envs/jupytervenv/bin/fast-lineage-caller", line 62, in <module>
    lineage_caller_vcf.assign_lineage_from_vcf_snp_counts(name_file, args.input_file, d[0], d[1], d[2], d[3], print_header, args.out, keep_red, pass_filter)
  File "/home/kin672/anaconda3/envs/jupytervenv/lib/python3.10/site-packages/fast_lineage_caller/lineage_caller_vcf.py", line 65, in assign_lineage_from_vcf_snp_counts
    with open(vcf, "r") as inp:
FileNotFoundError: [Errno 2] No such file or directory: 'Serialsamples.XD00912003.dedup_reads.bam.indelqualed_reads.bam.vars.vcf'
Traceback (most recent call last):
  File "/home/kin672/anaconda3/envs/jupytervenv/bin/fast-lineage-caller", line 62, in <module>
    lineage_caller_vcf.assign_lineage_from_vcf_snp_counts(name_file, args.input_file, d[0], d[1], d[2], d[3], print_header, args.out, keep_red, pass_filter)
  File "/home/kin672/anaconda3/envs/jupytervenv/lib/python3.10/site-packages/fast_lineage_caller/lineage_caller_vcf.py", line 65, in assign_lineage_from_vcf_snp_counts
    with open(vcf, "r") as inp:
FileNotFoundError: [Errno 2] No such file or directory: 'TB-111-18660-18-138_S11_R.all.vcf'
Traceback (most recent call last):
  File "/home/kin672/anaconda3/envs/jupytervenv/bin/fast-lineage-caller", line 62, in <module>
    lineage_caller_vcf.assign_lineage_from_vcf_snp_counts(name_file, args.input_file, d[0], d[1], d[2], d[3], print_header, args.out, keep_red, pass_filter)
  File "/home/kin672/anaconda3/envs/jupytervenv/lib/python3.10/site-packages/fast_lineage_caller/lineage_caller_vcf.py", line 65, in assign_lineage_from_vcf_snp_counts
    with open(vcf, "r") as inp:
FileNotFoundError: [Errno 2] No such file or directory: 'TB-111-17827-18_S136_R.all.vcf'
Traceback (most recent call last):
  File "/home/kin672/anaconda3/envs/jupytervenv/bin/fast-lineage-caller", line 62, in <module>
    lineage_caller_vcf.assign_lineage_from_vcf_snp_counts(name_file, args.input_file, d[0], d[1], d[2], d[3], print_header, args.out, keep_red, pass_filter)
  File "/home/kin672/anaconda3/envs/jupytervenv/lib/python3.10/site-packages/fast_lineage_caller/lineage_caller_vcf.py", line 65, in assign_lineage_from_vcf_snp_counts
    with open(vcf, "r") as inp:
FileNotFoundError: [Errno 2] No such file or directory: 'TB-111-19690-18_S174_R.all.vcf'
Traceback (most recent call last):
  File "/home/kin672/anaconda3/envs/jupytervenv/bin/fast-lineage-caller", line 62, in <module>
    lineage_caller_vcf.assign_lineage_from_vcf_snp_counts(name_file, args.input_file, d[0], d[1], d[2], d[3], print_header, args.out, keep_red, pass_filter)
  File "/home/kin672/anaconda3/envs/jupytervenv/lib/python3.10/site-packages/fast_lineage_caller/lineage_caller_vcf.py", line 65, in assign_lineage_from_vcf_snp_counts
    with open(vcf, "r") as inp:
FileNotFoundError: [Errno 2] No such file or directory: 'TB-111-19597-18_S76_R.all.vcf'
Traceback (most recent call last):
  File "/home/kin672/anaconda3/envs/jupytervenv/bin/fast-lineage-caller", line 62, in <module>
    lineage_caller_vcf.assign_lineage_from_vcf_snp_counts(name_file, args.input_file, d[0], d[1], d[2], d[3], print_header, args.out, keep_red, pass_filter)
  File "/home/kin672/anaconda3/envs/jupytervenv/lib/python3.10/site-packages/fast_lineage_caller/lineage_caller_vcf.py", line 65, in assign_lineage_from_vcf_snp_counts
    with open(vcf, "r") as inp:
FileNotFoundError: [Errno 2] No such file or directory: 'TB-111-17928-19_S69_R.all.vcf'
Traceback (most recent call last):
  File "/home/kin672/anaconda3/envs/jupytervenv/bin/fast-lineage-caller", line 62, in <module>
    lineage_caller_vcf.assign_lineage_from_vcf_snp_counts(name_file, args.input_file, d[0], d[1], d[2], d[3], print_header, args.out, keep_red, pass_filter)
  File "/home/kin672/anaconda3/envs/jupytervenv/lib/python3.10/site-packages/fast_lineage_caller/lineage_caller_vcf.py", line 65, in assign_lineage_from_vcf_snp_counts
    with open(vcf, "r") as inp:
FileNotFoundError: [Errno 2] No such file or directory: 'TB-111-16595-18-138_S100_R.all.vcf'
Traceback (most recent call last):
  File "/home/kin672/anaconda3/envs/jupytervenv/bin/fast-lineage-caller", line 62, in <module>
    lineage_caller_vcf.assign_lineage_from_vcf_snp_counts(name_file, args.input_file, d[0], d[1], d[2], d[3], print_header, args.out, keep_red, pass_filter)
  File "/home/kin672/anaconda3/envs/jupytervenv/lib/python3.10/site-packages/fast_lineage_caller/lineage_caller_vcf.py", line 65, in assign_lineage_from_vcf_snp_counts
    with open(vcf, "r") as inp:
FileNotFoundError: [Errno 2] No such file or directory: 'TB-111-20412-18_S17_R.all.vcf'
Traceback (most recent call last):
  File "/home/kin672/anaconda3/envs/jupytervenv/bin/fast-lineage-caller", line 62, in <module>
    lineage_caller_vcf.assign_lineage_from_vcf_snp_counts(name_file, args.input_file, d[0], d[1], d[2], d[3], print_header, args.out, keep_red, pass_filter)
  File "/home/kin672/anaconda3/envs/jupytervenv/lib/python3.10/site-packages/fast_lineage_caller/lineage_caller_vcf.py", line 65, in assign_lineage_from_vcf_snp_counts
    with open(vcf, "r") as inp:
FileNotFoundError: [Errno 2] No such file or directory: 'TB-111-16594-18_S127_R.all.vcf'
Traceback (most recent call last):
  File "/home/kin672/anaconda3/envs/jupytervenv/bin/fast-lineage-caller", line 62, in <module>
    lineage_caller_vcf.assign_lineage_from_vcf_snp_counts(name_file, args.input_file, d[0], d[1], d[2], d[3], print_header, args.out, keep_red, pass_filter)
  File "/home/kin672/anaconda3/envs/jupytervenv/lib/python3.10/site-packages/fast_lineage_caller/lineage_caller_vcf.py", line 65, in assign_lineage_from_vcf_snp_counts
    with open(vcf, "r") as inp:
FileNotFoundError: [Errno 2] No such file or directory: 'TB-111-19680-19_S148_R.all.vcf'
Traceback (most recent call last):
  File "/home/kin672/anaconda3/envs/jupytervenv/bin/fast-lineage-caller", line 62, in <module>
    lineage_caller_vcf.assign_lineage_from_vcf_snp_counts(name_file, args.input_file, d[0], d[1], d[2], d[3], print_header, args.out, keep_red, pass_filter)
  File "/home/kin672/anaconda3/envs/jupytervenv/lib/python3.10/site-packages/fast_lineage_caller/lineage_caller_vcf.py", line 65, in assign_lineage_from_vcf_snp_counts
    with open(vcf, "r") as inp:
FileNotFoundError: [Errno 2] No such file or directory: 'TB-111-16603-18_S112_R.all.vcf'
Traceback (most recent call last):
  File "/home/kin672/anaconda3/envs/jupytervenv/bin/fast-lineage-caller", line 62, in <module>
    lineage_caller_vcf.assign_lineage_from_vcf_snp_counts(name_file, args.input_file, d[0], d[1], d[2], d[3], print_header, args.out, keep_red, pass_filter)
  File "/home/kin672/anaconda3/envs/jupytervenv/lib/python3.10/site-packages/fast_lineage_caller/lineage_caller_vcf.py", line 65, in assign_lineage_from_vcf_snp_counts
    with open(vcf, "r") as inp:
FileNotFoundError: [Errno 2] No such file or directory: 'TB-111-16652-18_S134_R.all.vcf'
